Performing system checks...

System check identified no issues (0 silenced).
March 13, 2025 - 09:32:42
Django version 4.2.16, using settings 'dashboard.settings'
Starting development server at http://0.0.0.0:8000/
Quit the server with CONTROL-C.

Performing system checks...

System check identified no issues (0 silenced).
March 13, 2025 - 09:32:56
Django version 4.2.16, using settings 'dashboard.settings'
Starting development server at http://0.0.0.0:8000/
Quit the server with CONTROL-C.

Performing system checks...

System check identified no issues (0 silenced).
March 13, 2025 - 09:32:50
Django version 4.2.16, using settings 'dashboard.settings'
Starting development server at http://0.0.0.0:8000/
Quit the server with CONTROL-C.

Performing system checks...

System check identified no issues (0 silenced).
March 13, 2025 - 09:58:15
Django version 4.2.16, using settings 'dashboard.settings'
Starting development server at http://0.0.0.0:8000/
Quit the server with CONTROL-C.

Performing system checks...

System check identified no issues (0 silenced).
March 13, 2025 - 09:58:16
Django version 4.2.16, using settings 'dashboard.settings'
Starting development server at http://0.0.0.0:8000/
Quit the server with CONTROL-C.

Performing system checks...

System check identified no issues (0 silenced).
March 13, 2025 - 09:58:16
Django version 4.2.16, using settings 'dashboard.settings'
Starting development server at http://0.0.0.0:8000/
Quit the server with CONTROL-C.

Performing system checks...

System check identified no issues (0 silenced).
March 16, 2025 - 07:36:32
Django version 4.2.16, using settings 'dashboard.settings'
Starting development server at http://0.0.0.0:8000/
Quit the server with CONTROL-C.

Performing system checks...

System check identified no issues (0 silenced).
March 16, 2025 - 07:36:32
Django version 4.2.16, using settings 'dashboard.settings'
Starting development server at http://0.0.0.0:8000/
Quit the server with CONTROL-C.

Performing system checks...

System check identified no issues (0 silenced).
March 16, 2025 - 07:36:32
Django version 4.2.16, using settings 'dashboard.settings'
Starting development server at http://0.0.0.0:8000/
Quit the server with CONTROL-C.

Performing system checks...

System check identified no issues (0 silenced).
March 16, 2025 - 07:46:52
Django version 4.2.16, using settings 'dashboard.settings'
Starting development server at http://0.0.0.0:8000/
Quit the server with CONTROL-C.

Performing system checks...

System check identified no issues (0 silenced).
March 16, 2025 - 07:46:52
Django version 4.2.16, using settings 'dashboard.settings'
Starting development server at http://0.0.0.0:8000/
Quit the server with CONTROL-C.

Performing system checks...

System check identified no issues (0 silenced).
March 16, 2025 - 07:46:51
Django version 4.2.16, using settings 'dashboard.settings'
Starting development server at http://0.0.0.0:8000/
Quit the server with CONTROL-C.

Exception in thread django-main-thread:
Traceback (most recent call last):
  File "/usr/lib/python3.8/threading.py", line 932, in _bootstrap_inner
    self.run()
  File "/usr/lib/python3.8/threading.py", line 870, in run
    self._target(*self._args, **self._kwargs)
  File "/var/www/uwsgi/dashboard/venv/lib/python3.8/site-packages/django/utils/autoreload.py", line 64, in wrapper
    fn(*args, **kwargs)
  File "/var/www/uwsgi/dashboard/venv/lib/python3.8/site-packages/django/core/management/commands/runserver.py", line 133, in inner_run
    self.check(display_num_errors=True)
  File "/var/www/uwsgi/dashboard/venv/lib/python3.8/site-packages/django/core/management/base.py", line 485, in check
    all_issues = checks.run_checks(
  File "/var/www/uwsgi/dashboard/venv/lib/python3.8/site-packages/django/core/checks/registry.py", line 88, in run_checks
    new_errors = check(app_configs=app_configs, databases=databases)
  File "/var/www/uwsgi/dashboard/venv/lib/python3.8/site-packages/django/core/checks/urls.py", line 14, in check_url_config
    return check_resolver(resolver)
  File "/var/www/uwsgi/dashboard/venv/lib/python3.8/site-packages/django/core/checks/urls.py", line 24, in check_resolver
    return check_method()
  File "/var/www/uwsgi/dashboard/venv/lib/python3.8/site-packages/django/urls/resolvers.py", line 494, in check
    for pattern in self.url_patterns:
  File "/var/www/uwsgi/dashboard/venv/lib/python3.8/site-packages/django/utils/functional.py", line 57, in __get__
    res = instance.__dict__[self.name] = self.func(instance)
  File "/var/www/uwsgi/dashboard/venv/lib/python3.8/site-packages/django/urls/resolvers.py", line 715, in url_patterns
    patterns = getattr(self.urlconf_module, "urlpatterns", self.urlconf_module)
  File "/var/www/uwsgi/dashboard/venv/lib/python3.8/site-packages/django/utils/functional.py", line 57, in __get__
    res = instance.__dict__[self.name] = self.func(instance)
  File "/var/www/uwsgi/dashboard/venv/lib/python3.8/site-packages/django/urls/resolvers.py", line 708, in urlconf_module
    return import_module(self.urlconf_name)
  File "/usr/lib/python3.8/importlib/__init__.py", line 127, in import_module
    return _bootstrap._gcd_import(name[level:], package, level)
  File "<frozen importlib._bootstrap>", line 1014, in _gcd_import
  File "<frozen importlib._bootstrap>", line 991, in _find_and_load
  File "<frozen importlib._bootstrap>", line 975, in _find_and_load_unlocked
  File "<frozen importlib._bootstrap>", line 671, in _load_unlocked
  File "<frozen importlib._bootstrap_external>", line 848, in exec_module
  File "<frozen importlib._bootstrap>", line 219, in _call_with_frames_removed
  File "/var/www/uwsgi/dashboard/dashboard/urls.py", line 23, in <module>
    path('api/', include('dashboard_app.api_urls')),
  File "/var/www/uwsgi/dashboard/venv/lib/python3.8/site-packages/django/urls/conf.py", line 38, in include
    urlconf_module = import_module(urlconf_module)
  File "/usr/lib/python3.8/importlib/__init__.py", line 127, in import_module
    return _bootstrap._gcd_import(name[level:], package, level)
  File "<frozen importlib._bootstrap>", line 1014, in _gcd_import
  File "<frozen importlib._bootstrap>", line 991, in _find_and_load
  File "<frozen importlib._bootstrap>", line 975, in _find_and_load_unlocked
  File "<frozen importlib._bootstrap>", line 671, in _load_unlocked
  File "<frozen importlib._bootstrap_external>", line 848, in exec_module
  File "<frozen importlib._bootstrap>", line 219, in _call_with_frames_removed
  File "/var/www/uwsgi/dashboard/dashboard_app/api_urls.py", line 19, in <module>
    path('password-reset/', views.password_reset_request, name='password_reset_request'),
AttributeError: module 'dashboard_app.views' has no attribute 'password_reset_request'
Exception in thread django-main-thread:
Traceback (most recent call last):
  File "/usr/lib/python3.8/threading.py", line 932, in _bootstrap_inner
    self.run()
  File "/usr/lib/python3.8/threading.py", line 870, in run
    self._target(*self._args, **self._kwargs)
  File "/var/www/uwsgi/dashboard/venv/lib/python3.8/site-packages/django/utils/autoreload.py", line 64, in wrapper
    fn(*args, **kwargs)
  File "/var/www/uwsgi/dashboard/venv/lib/python3.8/site-packages/django/core/management/commands/runserver.py", line 133, in inner_run
    self.check(display_num_errors=True)
  File "/var/www/uwsgi/dashboard/venv/lib/python3.8/site-packages/django/core/management/base.py", line 485, in check
    all_issues = checks.run_checks(
  File "/var/www/uwsgi/dashboard/venv/lib/python3.8/site-packages/django/core/checks/registry.py", line 88, in run_checks
    new_errors = check(app_configs=app_configs, databases=databases)
  File "/var/www/uwsgi/dashboard/venv/lib/python3.8/site-packages/django/core/checks/urls.py", line 14, in check_url_config
    return check_resolver(resolver)
  File "/var/www/uwsgi/dashboard/venv/lib/python3.8/site-packages/django/core/checks/urls.py", line 24, in check_resolver
    return check_method()
  File "/var/www/uwsgi/dashboard/venv/lib/python3.8/site-packages/django/urls/resolvers.py", line 494, in check
    for pattern in self.url_patterns:
  File "/var/www/uwsgi/dashboard/venv/lib/python3.8/site-packages/django/utils/functional.py", line 57, in __get__
    res = instance.__dict__[self.name] = self.func(instance)
  File "/var/www/uwsgi/dashboard/venv/lib/python3.8/site-packages/django/urls/resolvers.py", line 715, in url_patterns
    patterns = getattr(self.urlconf_module, "urlpatterns", self.urlconf_module)
  File "/var/www/uwsgi/dashboard/venv/lib/python3.8/site-packages/django/utils/functional.py", line 57, in __get__
    res = instance.__dict__[self.name] = self.func(instance)
  File "/var/www/uwsgi/dashboard/venv/lib/python3.8/site-packages/django/urls/resolvers.py", line 708, in urlconf_module
    return import_module(self.urlconf_name)
  File "/usr/lib/python3.8/importlib/__init__.py", line 127, in import_module
    return _bootstrap._gcd_import(name[level:], package, level)
  File "<frozen importlib._bootstrap>", line 1014, in _gcd_import
  File "<frozen importlib._bootstrap>", line 991, in _find_and_load
  File "<frozen importlib._bootstrap>", line 975, in _find_and_load_unlocked
  File "<frozen importlib._bootstrap>", line 671, in _load_unlocked
  File "<frozen importlib._bootstrap_external>", line 848, in exec_module
  File "<frozen importlib._bootstrap>", line 219, in _call_with_frames_removed
  File "/var/www/uwsgi/dashboard/dashboard/urls.py", line 23, in <module>
    path('api/', include('dashboard_app.api_urls')),
  File "/var/www/uwsgi/dashboard/venv/lib/python3.8/site-packages/django/urls/conf.py", line 38, in include
    urlconf_module = import_module(urlconf_module)
  File "/usr/lib/python3.8/importlib/__init__.py", line 127, in import_module
    return _bootstrap._gcd_import(name[level:], package, level)
  File "<frozen importlib._bootstrap>", line 1014, in _gcd_import
  File "<frozen importlib._bootstrap>", line 991, in _find_and_load
  File "<frozen importlib._bootstrap>", line 975, in _find_and_load_unlocked
  File "<frozen importlib._bootstrap>", line 671, in _load_unlocked
  File "<frozen importlib._bootstrap_external>", line 848, in exec_module
  File "<frozen importlib._bootstrap>", line 219, in _call_with_frames_removed
  File "/var/www/uwsgi/dashboard/dashboard_app/api_urls.py", line 19, in <module>
    path('password-reset/', views.password_reset_request, name='password_reset_request'),
AttributeError: module 'dashboard_app.views' has no attribute 'password_reset_request'
Exception in thread django-main-thread:
Traceback (most recent call last):
  File "/usr/lib/python3.8/threading.py", line 932, in _bootstrap_inner
    self.run()
  File "/usr/lib/python3.8/threading.py", line 870, in run
    self._target(*self._args, **self._kwargs)
  File "/var/www/uwsgi/dashboard/venv/lib/python3.8/site-packages/django/utils/autoreload.py", line 64, in wrapper
    fn(*args, **kwargs)
  File "/var/www/uwsgi/dashboard/venv/lib/python3.8/site-packages/django/core/management/commands/runserver.py", line 133, in inner_run
    self.check(display_num_errors=True)
  File "/var/www/uwsgi/dashboard/venv/lib/python3.8/site-packages/django/core/management/base.py", line 485, in check
    all_issues = checks.run_checks(
  File "/var/www/uwsgi/dashboard/venv/lib/python3.8/site-packages/django/core/checks/registry.py", line 88, in run_checks
    new_errors = check(app_configs=app_configs, databases=databases)
  File "/var/www/uwsgi/dashboard/venv/lib/python3.8/site-packages/django/core/checks/urls.py", line 14, in check_url_config
    return check_resolver(resolver)
  File "/var/www/uwsgi/dashboard/venv/lib/python3.8/site-packages/django/core/checks/urls.py", line 24, in check_resolver
    return check_method()
  File "/var/www/uwsgi/dashboard/venv/lib/python3.8/site-packages/django/urls/resolvers.py", line 494, in check
    for pattern in self.url_patterns:
  File "/var/www/uwsgi/dashboard/venv/lib/python3.8/site-packages/django/utils/functional.py", line 57, in __get__
    res = instance.__dict__[self.name] = self.func(instance)
  File "/var/www/uwsgi/dashboard/venv/lib/python3.8/site-packages/django/urls/resolvers.py", line 715, in url_patterns
    patterns = getattr(self.urlconf_module, "urlpatterns", self.urlconf_module)
  File "/var/www/uwsgi/dashboard/venv/lib/python3.8/site-packages/django/utils/functional.py", line 57, in __get__
    res = instance.__dict__[self.name] = self.func(instance)
  File "/var/www/uwsgi/dashboard/venv/lib/python3.8/site-packages/django/urls/resolvers.py", line 708, in urlconf_module
    return import_module(self.urlconf_name)
  File "/usr/lib/python3.8/importlib/__init__.py", line 127, in import_module
    return _bootstrap._gcd_import(name[level:], package, level)
  File "<frozen importlib._bootstrap>", line 1014, in _gcd_import
  File "<frozen importlib._bootstrap>", line 991, in _find_and_load
  File "<frozen importlib._bootstrap>", line 975, in _find_and_load_unlocked
  File "<frozen importlib._bootstrap>", line 671, in _load_unlocked
  File "<frozen importlib._bootstrap_external>", line 848, in exec_module
  File "<frozen importlib._bootstrap>", line 219, in _call_with_frames_removed
  File "/var/www/uwsgi/dashboard/dashboard/urls.py", line 23, in <module>
    path('api/', include('dashboard_app.api_urls')),
  File "/var/www/uwsgi/dashboard/venv/lib/python3.8/site-packages/django/urls/conf.py", line 38, in include
    urlconf_module = import_module(urlconf_module)
  File "/usr/lib/python3.8/importlib/__init__.py", line 127, in import_module
    return _bootstrap._gcd_import(name[level:], package, level)
  File "<frozen importlib._bootstrap>", line 1014, in _gcd_import
  File "<frozen importlib._bootstrap>", line 991, in _find_and_load
  File "<frozen importlib._bootstrap>", line 975, in _find_and_load_unlocked
  File "<frozen importlib._bootstrap>", line 671, in _load_unlocked
  File "<frozen importlib._bootstrap_external>", line 848, in exec_module
  File "<frozen importlib._bootstrap>", line 219, in _call_with_frames_removed
  File "/var/www/uwsgi/dashboard/dashboard_app/api_urls.py", line 19, in <module>
    path('password-reset/', views.password_reset_request, name='password_reset_request'),
AttributeError: module 'dashboard_app.views' has no attribute 'password_reset_request'
Performing system checks...

Performing system checks...

Exception in thread django-main-thread:
Traceback (most recent call last):
  File "/usr/lib/python3.8/threading.py", line 932, in _bootstrap_inner
    self.run()
  File "/usr/lib/python3.8/threading.py", line 870, in run
    self._target(*self._args, **self._kwargs)
  File "/var/www/uwsgi/dashboard/venv/lib/python3.8/site-packages/django/utils/autoreload.py", line 64, in wrapper
    fn(*args, **kwargs)
  File "/var/www/uwsgi/dashboard/venv/lib/python3.8/site-packages/django/core/management/commands/runserver.py", line 133, in inner_run
    self.check(display_num_errors=True)
  File "/var/www/uwsgi/dashboard/venv/lib/python3.8/site-packages/django/core/management/base.py", line 485, in check
    all_issues = checks.run_checks(
  File "/var/www/uwsgi/dashboard/venv/lib/python3.8/site-packages/django/core/checks/registry.py", line 88, in run_checks
    new_errors = check(app_configs=app_configs, databases=databases)
  File "/var/www/uwsgi/dashboard/venv/lib/python3.8/site-packages/django/core/checks/urls.py", line 14, in check_url_config
    return check_resolver(resolver)
  File "/var/www/uwsgi/dashboard/venv/lib/python3.8/site-packages/django/core/checks/urls.py", line 24, in check_resolver
    return check_method()
  File "/var/www/uwsgi/dashboard/venv/lib/python3.8/site-packages/django/urls/resolvers.py", line 494, in check
    for pattern in self.url_patterns:
  File "/var/www/uwsgi/dashboard/venv/lib/python3.8/site-packages/django/utils/functional.py", line 57, in __get__
    res = instance.__dict__[self.name] = self.func(instance)
  File "/var/www/uwsgi/dashboard/venv/lib/python3.8/site-packages/django/urls/resolvers.py", line 715, in url_patterns
    patterns = getattr(self.urlconf_module, "urlpatterns", self.urlconf_module)
  File "/var/www/uwsgi/dashboard/venv/lib/python3.8/site-packages/django/utils/functional.py", line 57, in __get__
    res = instance.__dict__[self.name] = self.func(instance)
  File "/var/www/uwsgi/dashboard/venv/lib/python3.8/site-packages/django/urls/resolvers.py", line 708, in urlconf_module
    return import_module(self.urlconf_name)
  File "/usr/lib/python3.8/importlib/__init__.py", line 127, in import_module
    return _bootstrap._gcd_import(name[level:], package, level)
  File "<frozen importlib._bootstrap>", line 1014, in _gcd_import
  File "<frozen importlib._bootstrap>", line 991, in _find_and_load
  File "<frozen importlib._bootstrap>", line 975, in _find_and_load_unlocked
  File "<frozen importlib._bootstrap>", line 671, in _load_unlocked
  File "<frozen importlib._bootstrap_external>", line 848, in exec_module
  File "<frozen importlib._bootstrap>", line 219, in _call_with_frames_removed
  File "/var/www/uwsgi/dashboard/dashboard/urls.py", line 23, in <module>
    path('api/', include('dashboard_app.api_urls')),
  File "/var/www/uwsgi/dashboard/venv/lib/python3.8/site-packages/django/urls/conf.py", line 38, in include
    urlconf_module = import_module(urlconf_module)
  File "/usr/lib/python3.8/importlib/__init__.py", line 127, in import_module
    return _bootstrap._gcd_import(name[level:], package, level)
  File "<frozen importlib._bootstrap>", line 1014, in _gcd_import
  File "<frozen importlib._bootstrap>", line 991, in _find_and_load
  File "<frozen importlib._bootstrap>", line 975, in _find_and_load_unlocked
  File "<frozen importlib._bootstrap>", line 671, in _load_unlocked
  File "<frozen importlib._bootstrap_external>", line 848, in exec_module
  File "<frozen importlib._bootstrap>", line 219, in _call_with_frames_removed
  File "/var/www/uwsgi/dashboard/dashboard_app/api_urls.py", line 19, in <module>
    path('password-reset/', views.password_reset_request, name='password_reset_request'),
AttributeError: module 'dashboard_app.views' has no attribute 'password_reset_request'
Exception in thread django-main-thread:
Traceback (most recent call last):
  File "/usr/lib/python3.8/threading.py", line 932, in _bootstrap_inner
    self.run()
  File "/usr/lib/python3.8/threading.py", line 870, in run
    self._target(*self._args, **self._kwargs)
  File "/var/www/uwsgi/dashboard/venv/lib/python3.8/site-packages/django/utils/autoreload.py", line 64, in wrapper
    fn(*args, **kwargs)
  File "/var/www/uwsgi/dashboard/venv/lib/python3.8/site-packages/django/core/management/commands/runserver.py", line 133, in inner_run
    self.check(display_num_errors=True)
  File "/var/www/uwsgi/dashboard/venv/lib/python3.8/site-packages/django/core/management/base.py", line 485, in check
    all_issues = checks.run_checks(
  File "/var/www/uwsgi/dashboard/venv/lib/python3.8/site-packages/django/core/checks/registry.py", line 88, in run_checks
    new_errors = check(app_configs=app_configs, databases=databases)
  File "/var/www/uwsgi/dashboard/venv/lib/python3.8/site-packages/django/core/checks/urls.py", line 14, in check_url_config
    return check_resolver(resolver)
  File "/var/www/uwsgi/dashboard/venv/lib/python3.8/site-packages/django/core/checks/urls.py", line 24, in check_resolver
    return check_method()
  File "/var/www/uwsgi/dashboard/venv/lib/python3.8/site-packages/django/urls/resolvers.py", line 494, in check
    for pattern in self.url_patterns:
  File "/var/www/uwsgi/dashboard/venv/lib/python3.8/site-packages/django/utils/functional.py", line 57, in __get__
    res = instance.__dict__[self.name] = self.func(instance)
  File "/var/www/uwsgi/dashboard/venv/lib/python3.8/site-packages/django/urls/resolvers.py", line 715, in url_patterns
    patterns = getattr(self.urlconf_module, "urlpatterns", self.urlconf_module)
  File "/var/www/uwsgi/dashboard/venv/lib/python3.8/site-packages/django/utils/functional.py", line 57, in __get__
    res = instance.__dict__[self.name] = self.func(instance)
  File "/var/www/uwsgi/dashboard/venv/lib/python3.8/site-packages/django/urls/resolvers.py", line 708, in urlconf_module
    return import_module(self.urlconf_name)
  File "/usr/lib/python3.8/importlib/__init__.py", line 127, in import_module
    return _bootstrap._gcd_import(name[level:], package, level)
  File "<frozen importlib._bootstrap>", line 1014, in _gcd_import
  File "<frozen importlib._bootstrap>", line 991, in _find_and_load
  File "<frozen importlib._bootstrap>", line 975, in _find_and_load_unlocked
  File "<frozen importlib._bootstrap>", line 671, in _load_unlocked
  File "<frozen importlib._bootstrap_external>", line 848, in exec_module
  File "<frozen importlib._bootstrap>", line 219, in _call_with_frames_removed
  File "/var/www/uwsgi/dashboard/dashboard/urls.py", line 23, in <module>
    path('api/', include('dashboard_app.api_urls')),
  File "/var/www/uwsgi/dashboard/venv/lib/python3.8/site-packages/django/urls/conf.py", line 38, in include
    urlconf_module = import_module(urlconf_module)
  File "/usr/lib/python3.8/importlib/__init__.py", line 127, in import_module
    return _bootstrap._gcd_import(name[level:], package, level)
  File "<frozen importlib._bootstrap>", line 1014, in _gcd_import
  File "<frozen importlib._bootstrap>", line 991, in _find_and_load
  File "<frozen importlib._bootstrap>", line 975, in _find_and_load_unlocked
  File "<frozen importlib._bootstrap>", line 671, in _load_unlocked
  File "<frozen importlib._bootstrap_external>", line 848, in exec_module
  File "<frozen importlib._bootstrap>", line 219, in _call_with_frames_removed
  File "/var/www/uwsgi/dashboard/dashboard_app/api_urls.py", line 19, in <module>
    path('password-reset/', views.password_reset_request, name='password_reset_request'),
AttributeError: module 'dashboard_app.views' has no attribute 'password_reset_request'
Performing system checks...

Exception in thread django-main-thread:
Traceback (most recent call last):
  File "/usr/lib/python3.8/threading.py", line 932, in _bootstrap_inner
    self.run()
  File "/usr/lib/python3.8/threading.py", line 870, in run
    self._target(*self._args, **self._kwargs)
  File "/var/www/uwsgi/dashboard/venv/lib/python3.8/site-packages/django/utils/autoreload.py", line 64, in wrapper
    fn(*args, **kwargs)
  File "/var/www/uwsgi/dashboard/venv/lib/python3.8/site-packages/django/core/management/commands/runserver.py", line 133, in inner_run
    self.check(display_num_errors=True)
  File "/var/www/uwsgi/dashboard/venv/lib/python3.8/site-packages/django/core/management/base.py", line 485, in check
    all_issues = checks.run_checks(
  File "/var/www/uwsgi/dashboard/venv/lib/python3.8/site-packages/django/core/checks/registry.py", line 88, in run_checks
    new_errors = check(app_configs=app_configs, databases=databases)
  File "/var/www/uwsgi/dashboard/venv/lib/python3.8/site-packages/django/core/checks/urls.py", line 14, in check_url_config
    return check_resolver(resolver)
  File "/var/www/uwsgi/dashboard/venv/lib/python3.8/site-packages/django/core/checks/urls.py", line 24, in check_resolver
    return check_method()
  File "/var/www/uwsgi/dashboard/venv/lib/python3.8/site-packages/django/urls/resolvers.py", line 494, in check
    for pattern in self.url_patterns:
  File "/var/www/uwsgi/dashboard/venv/lib/python3.8/site-packages/django/utils/functional.py", line 57, in __get__
    res = instance.__dict__[self.name] = self.func(instance)
  File "/var/www/uwsgi/dashboard/venv/lib/python3.8/site-packages/django/urls/resolvers.py", line 715, in url_patterns
    patterns = getattr(self.urlconf_module, "urlpatterns", self.urlconf_module)
  File "/var/www/uwsgi/dashboard/venv/lib/python3.8/site-packages/django/utils/functional.py", line 57, in __get__
    res = instance.__dict__[self.name] = self.func(instance)
  File "/var/www/uwsgi/dashboard/venv/lib/python3.8/site-packages/django/urls/resolvers.py", line 708, in urlconf_module
    return import_module(self.urlconf_name)
  File "/usr/lib/python3.8/importlib/__init__.py", line 127, in import_module
    return _bootstrap._gcd_import(name[level:], package, level)
  File "<frozen importlib._bootstrap>", line 1014, in _gcd_import
  File "<frozen importlib._bootstrap>", line 991, in _find_and_load
  File "<frozen importlib._bootstrap>", line 975, in _find_and_load_unlocked
  File "<frozen importlib._bootstrap>", line 671, in _load_unlocked
  File "<frozen importlib._bootstrap_external>", line 848, in exec_module
  File "<frozen importlib._bootstrap>", line 219, in _call_with_frames_removed
  File "/var/www/uwsgi/dashboard/dashboard/urls.py", line 23, in <module>
    path('api/', include('dashboard_app.api_urls')),
  File "/var/www/uwsgi/dashboard/venv/lib/python3.8/site-packages/django/urls/conf.py", line 38, in include
    urlconf_module = import_module(urlconf_module)
  File "/usr/lib/python3.8/importlib/__init__.py", line 127, in import_module
    return _bootstrap._gcd_import(name[level:], package, level)
  File "<frozen importlib._bootstrap>", line 1014, in _gcd_import
  File "<frozen importlib._bootstrap>", line 991, in _find_and_load
  File "<frozen importlib._bootstrap>", line 975, in _find_and_load_unlocked
  File "<frozen importlib._bootstrap>", line 671, in _load_unlocked
  File "<frozen importlib._bootstrap_external>", line 848, in exec_module
  File "<frozen importlib._bootstrap>", line 219, in _call_with_frames_removed
  File "/var/www/uwsgi/dashboard/dashboard_app/api_urls.py", line 19, in <module>
    path('password-reset/', views.password_reset_request, name='password_reset_request'),
AttributeError: module 'dashboard_app.views' has no attribute 'password_reset_request'
Performing system checks...

Performing system checks...

Exception in thread django-main-thread:
Traceback (most recent call last):
  File "/usr/lib/python3.8/threading.py", line 932, in _bootstrap_inner
    self.run()
  File "/usr/lib/python3.8/threading.py", line 870, in run
    self._target(*self._args, **self._kwargs)
  File "/var/www/uwsgi/dashboard/venv/lib/python3.8/site-packages/django/utils/autoreload.py", line 64, in wrapper
    fn(*args, **kwargs)
  File "/var/www/uwsgi/dashboard/venv/lib/python3.8/site-packages/django/core/management/commands/runserver.py", line 133, in inner_run
    self.check(display_num_errors=True)
  File "/var/www/uwsgi/dashboard/venv/lib/python3.8/site-packages/django/core/management/base.py", line 485, in check
    all_issues = checks.run_checks(
  File "/var/www/uwsgi/dashboard/venv/lib/python3.8/site-packages/django/core/checks/registry.py", line 88, in run_checks
    new_errors = check(app_configs=app_configs, databases=databases)
  File "/var/www/uwsgi/dashboard/venv/lib/python3.8/site-packages/django/core/checks/urls.py", line 14, in check_url_config
    return check_resolver(resolver)
  File "/var/www/uwsgi/dashboard/venv/lib/python3.8/site-packages/django/core/checks/urls.py", line 24, in check_resolver
    return check_method()
  File "/var/www/uwsgi/dashboard/venv/lib/python3.8/site-packages/django/urls/resolvers.py", line 494, in check
    for pattern in self.url_patterns:
  File "/var/www/uwsgi/dashboard/venv/lib/python3.8/site-packages/django/utils/functional.py", line 57, in __get__
    res = instance.__dict__[self.name] = self.func(instance)
  File "/var/www/uwsgi/dashboard/venv/lib/python3.8/site-packages/django/urls/resolvers.py", line 715, in url_patterns
    patterns = getattr(self.urlconf_module, "urlpatterns", self.urlconf_module)
  File "/var/www/uwsgi/dashboard/venv/lib/python3.8/site-packages/django/utils/functional.py", line 57, in __get__
    res = instance.__dict__[self.name] = self.func(instance)
  File "/var/www/uwsgi/dashboard/venv/lib/python3.8/site-packages/django/urls/resolvers.py", line 708, in urlconf_module
    return import_module(self.urlconf_name)
  File "/usr/lib/python3.8/importlib/__init__.py", line 127, in import_module
    return _bootstrap._gcd_import(name[level:], package, level)
  File "<frozen importlib._bootstrap>", line 1014, in _gcd_import
  File "<frozen importlib._bootstrap>", line 991, in _find_and_load
  File "<frozen importlib._bootstrap>", line 975, in _find_and_load_unlocked
  File "<frozen importlib._bootstrap>", line 671, in _load_unlocked
  File "<frozen importlib._bootstrap_external>", line 848, in exec_module
  File "<frozen importlib._bootstrap>", line 219, in _call_with_frames_removed
  File "/var/www/uwsgi/dashboard/dashboard/urls.py", line 23, in <module>
    path('api/', include('dashboard_app.api_urls')),
  File "/var/www/uwsgi/dashboard/venv/lib/python3.8/site-packages/django/urls/conf.py", line 38, in include
    urlconf_module = import_module(urlconf_module)
  File "/usr/lib/python3.8/importlib/__init__.py", line 127, in import_module
    return _bootstrap._gcd_import(name[level:], package, level)
  File "<frozen importlib._bootstrap>", line 1014, in _gcd_import
  File "<frozen importlib._bootstrap>", line 991, in _find_and_load
  File "<frozen importlib._bootstrap>", line 975, in _find_and_load_unlocked
  File "<frozen importlib._bootstrap>", line 671, in _load_unlocked
  File "<frozen importlib._bootstrap_external>", line 848, in exec_module
  File "<frozen importlib._bootstrap>", line 219, in _call_with_frames_removed
  File "/var/www/uwsgi/dashboard/dashboard_app/api_urls.py", line 19, in <module>
    path('password-reset/', views.password_reset_request, name='password_reset_request'),
AttributeError: module 'dashboard_app.views' has no attribute 'password_reset_request'
Exception in thread django-main-thread:
Traceback (most recent call last):
  File "/usr/lib/python3.8/threading.py", line 932, in _bootstrap_inner
    self.run()
  File "/usr/lib/python3.8/threading.py", line 870, in run
    self._target(*self._args, **self._kwargs)
  File "/var/www/uwsgi/dashboard/venv/lib/python3.8/site-packages/django/utils/autoreload.py", line 64, in wrapper
    fn(*args, **kwargs)
  File "/var/www/uwsgi/dashboard/venv/lib/python3.8/site-packages/django/core/management/commands/runserver.py", line 133, in inner_run
    self.check(display_num_errors=True)
  File "/var/www/uwsgi/dashboard/venv/lib/python3.8/site-packages/django/core/management/base.py", line 485, in check
    all_issues = checks.run_checks(
  File "/var/www/uwsgi/dashboard/venv/lib/python3.8/site-packages/django/core/checks/registry.py", line 88, in run_checks
    new_errors = check(app_configs=app_configs, databases=databases)
  File "/var/www/uwsgi/dashboard/venv/lib/python3.8/site-packages/django/core/checks/urls.py", line 14, in check_url_config
    return check_resolver(resolver)
  File "/var/www/uwsgi/dashboard/venv/lib/python3.8/site-packages/django/core/checks/urls.py", line 24, in check_resolver
    return check_method()
  File "/var/www/uwsgi/dashboard/venv/lib/python3.8/site-packages/django/urls/resolvers.py", line 494, in check
    for pattern in self.url_patterns:
  File "/var/www/uwsgi/dashboard/venv/lib/python3.8/site-packages/django/utils/functional.py", line 57, in __get__
    res = instance.__dict__[self.name] = self.func(instance)
  File "/var/www/uwsgi/dashboard/venv/lib/python3.8/site-packages/django/urls/resolvers.py", line 715, in url_patterns
    patterns = getattr(self.urlconf_module, "urlpatterns", self.urlconf_module)
  File "/var/www/uwsgi/dashboard/venv/lib/python3.8/site-packages/django/utils/functional.py", line 57, in __get__
    res = instance.__dict__[self.name] = self.func(instance)
  File "/var/www/uwsgi/dashboard/venv/lib/python3.8/site-packages/django/urls/resolvers.py", line 708, in urlconf_module
    return import_module(self.urlconf_name)
  File "/usr/lib/python3.8/importlib/__init__.py", line 127, in import_module
    return _bootstrap._gcd_import(name[level:], package, level)
  File "<frozen importlib._bootstrap>", line 1014, in _gcd_import
  File "<frozen importlib._bootstrap>", line 991, in _find_and_load
  File "<frozen importlib._bootstrap>", line 975, in _find_and_load_unlocked
  File "<frozen importlib._bootstrap>", line 671, in _load_unlocked
  File "<frozen importlib._bootstrap_external>", line 848, in exec_module
  File "<frozen importlib._bootstrap>", line 219, in _call_with_frames_removed
  File "/var/www/uwsgi/dashboard/dashboard/urls.py", line 23, in <module>
    path('api/', include('dashboard_app.api_urls')),
  File "/var/www/uwsgi/dashboard/venv/lib/python3.8/site-packages/django/urls/conf.py", line 38, in include
    urlconf_module = import_module(urlconf_module)
  File "/usr/lib/python3.8/importlib/__init__.py", line 127, in import_module
    return _bootstrap._gcd_import(name[level:], package, level)
  File "<frozen importlib._bootstrap>", line 1014, in _gcd_import
  File "<frozen importlib._bootstrap>", line 991, in _find_and_load
  File "<frozen importlib._bootstrap>", line 975, in _find_and_load_unlocked
  File "<frozen importlib._bootstrap>", line 671, in _load_unlocked
  File "<frozen importlib._bootstrap_external>", line 848, in exec_module
  File "<frozen importlib._bootstrap>", line 219, in _call_with_frames_removed
  File "/var/www/uwsgi/dashboard/dashboard_app/api_urls.py", line 19, in <module>
    path('password-reset/', views.password_reset_request, name='password_reset_request'),
AttributeError: module 'dashboard_app.views' has no attribute 'password_reset_request'
Performing system checks...

Exception in thread django-main-thread:
Traceback (most recent call last):
  File "/usr/lib/python3.8/threading.py", line 932, in _bootstrap_inner
    self.run()
  File "/usr/lib/python3.8/threading.py", line 870, in run
    self._target(*self._args, **self._kwargs)
  File "/var/www/uwsgi/dashboard/venv/lib/python3.8/site-packages/django/utils/autoreload.py", line 64, in wrapper
    fn(*args, **kwargs)
  File "/var/www/uwsgi/dashboard/venv/lib/python3.8/site-packages/django/core/management/commands/runserver.py", line 133, in inner_run
    self.check(display_num_errors=True)
  File "/var/www/uwsgi/dashboard/venv/lib/python3.8/site-packages/django/core/management/base.py", line 485, in check
    all_issues = checks.run_checks(
  File "/var/www/uwsgi/dashboard/venv/lib/python3.8/site-packages/django/core/checks/registry.py", line 88, in run_checks
    new_errors = check(app_configs=app_configs, databases=databases)
  File "/var/www/uwsgi/dashboard/venv/lib/python3.8/site-packages/django/core/checks/urls.py", line 14, in check_url_config
    return check_resolver(resolver)
  File "/var/www/uwsgi/dashboard/venv/lib/python3.8/site-packages/django/core/checks/urls.py", line 24, in check_resolver
    return check_method()
  File "/var/www/uwsgi/dashboard/venv/lib/python3.8/site-packages/django/urls/resolvers.py", line 494, in check
    for pattern in self.url_patterns:
  File "/var/www/uwsgi/dashboard/venv/lib/python3.8/site-packages/django/utils/functional.py", line 57, in __get__
    res = instance.__dict__[self.name] = self.func(instance)
  File "/var/www/uwsgi/dashboard/venv/lib/python3.8/site-packages/django/urls/resolvers.py", line 715, in url_patterns
    patterns = getattr(self.urlconf_module, "urlpatterns", self.urlconf_module)
  File "/var/www/uwsgi/dashboard/venv/lib/python3.8/site-packages/django/utils/functional.py", line 57, in __get__
    res = instance.__dict__[self.name] = self.func(instance)
  File "/var/www/uwsgi/dashboard/venv/lib/python3.8/site-packages/django/urls/resolvers.py", line 708, in urlconf_module
    return import_module(self.urlconf_name)
  File "/usr/lib/python3.8/importlib/__init__.py", line 127, in import_module
    return _bootstrap._gcd_import(name[level:], package, level)
  File "<frozen importlib._bootstrap>", line 1014, in _gcd_import
  File "<frozen importlib._bootstrap>", line 991, in _find_and_load
  File "<frozen importlib._bootstrap>", line 975, in _find_and_load_unlocked
  File "<frozen importlib._bootstrap>", line 671, in _load_unlocked
  File "<frozen importlib._bootstrap_external>", line 848, in exec_module
  File "<frozen importlib._bootstrap>", line 219, in _call_with_frames_removed
  File "/var/www/uwsgi/dashboard/dashboard/urls.py", line 23, in <module>
    path('api/', include('dashboard_app.api_urls')),
  File "/var/www/uwsgi/dashboard/venv/lib/python3.8/site-packages/django/urls/conf.py", line 38, in include
    urlconf_module = import_module(urlconf_module)
  File "/usr/lib/python3.8/importlib/__init__.py", line 127, in import_module
    return _bootstrap._gcd_import(name[level:], package, level)
  File "<frozen importlib._bootstrap>", line 1014, in _gcd_import
  File "<frozen importlib._bootstrap>", line 991, in _find_and_load
  File "<frozen importlib._bootstrap>", line 975, in _find_and_load_unlocked
  File "<frozen importlib._bootstrap>", line 671, in _load_unlocked
  File "<frozen importlib._bootstrap_external>", line 848, in exec_module
  File "<frozen importlib._bootstrap>", line 219, in _call_with_frames_removed
  File "/var/www/uwsgi/dashboard/dashboard_app/api_urls.py", line 19, in <module>
    path('password-reset/', views.password_reset_request, name='password_reset_request'),
AttributeError: module 'dashboard_app.views' has no attribute 'password_reset_request'
Performing system checks...

Performing system checks...

Exception in thread django-main-thread:
Traceback (most recent call last):
  File "/usr/lib/python3.8/threading.py", line 932, in _bootstrap_inner
    self.run()
  File "/usr/lib/python3.8/threading.py", line 870, in run
    self._target(*self._args, **self._kwargs)
  File "/var/www/uwsgi/dashboard/venv/lib/python3.8/site-packages/django/utils/autoreload.py", line 64, in wrapper
    fn(*args, **kwargs)
  File "/var/www/uwsgi/dashboard/venv/lib/python3.8/site-packages/django/core/management/commands/runserver.py", line 133, in inner_run
    self.check(display_num_errors=True)
  File "/var/www/uwsgi/dashboard/venv/lib/python3.8/site-packages/django/core/management/base.py", line 485, in check
    all_issues = checks.run_checks(
  File "/var/www/uwsgi/dashboard/venv/lib/python3.8/site-packages/django/core/checks/registry.py", line 88, in run_checks
    new_errors = check(app_configs=app_configs, databases=databases)
  File "/var/www/uwsgi/dashboard/venv/lib/python3.8/site-packages/django/core/checks/urls.py", line 14, in check_url_config
    return check_resolver(resolver)
  File "/var/www/uwsgi/dashboard/venv/lib/python3.8/site-packages/django/core/checks/urls.py", line 24, in check_resolver
    return check_method()
  File "/var/www/uwsgi/dashboard/venv/lib/python3.8/site-packages/django/urls/resolvers.py", line 494, in check
    for pattern in self.url_patterns:
  File "/var/www/uwsgi/dashboard/venv/lib/python3.8/site-packages/django/utils/functional.py", line 57, in __get__
    res = instance.__dict__[self.name] = self.func(instance)
  File "/var/www/uwsgi/dashboard/venv/lib/python3.8/site-packages/django/urls/resolvers.py", line 715, in url_patterns
    patterns = getattr(self.urlconf_module, "urlpatterns", self.urlconf_module)
  File "/var/www/uwsgi/dashboard/venv/lib/python3.8/site-packages/django/utils/functional.py", line 57, in __get__
    res = instance.__dict__[self.name] = self.func(instance)
  File "/var/www/uwsgi/dashboard/venv/lib/python3.8/site-packages/django/urls/resolvers.py", line 708, in urlconf_module
    return import_module(self.urlconf_name)
  File "/usr/lib/python3.8/importlib/__init__.py", line 127, in import_module
    return _bootstrap._gcd_import(name[level:], package, level)
  File "<frozen importlib._bootstrap>", line 1014, in _gcd_import
  File "<frozen importlib._bootstrap>", line 991, in _find_and_load
  File "<frozen importlib._bootstrap>", line 975, in _find_and_load_unlocked
  File "<frozen importlib._bootstrap>", line 671, in _load_unlocked
  File "<frozen importlib._bootstrap_external>", line 848, in exec_module
  File "<frozen importlib._bootstrap>", line 219, in _call_with_frames_removed
  File "/var/www/uwsgi/dashboard/dashboard/urls.py", line 23, in <module>
    path('api/', include('dashboard_app.api_urls')),
  File "/var/www/uwsgi/dashboard/venv/lib/python3.8/site-packages/django/urls/conf.py", line 38, in include
    urlconf_module = import_module(urlconf_module)
  File "/usr/lib/python3.8/importlib/__init__.py", line 127, in import_module
    return _bootstrap._gcd_import(name[level:], package, level)
  File "<frozen importlib._bootstrap>", line 1014, in _gcd_import
  File "<frozen importlib._bootstrap>", line 991, in _find_and_load
  File "<frozen importlib._bootstrap>", line 975, in _find_and_load_unlocked
  File "<frozen importlib._bootstrap>", line 671, in _load_unlocked
  File "<frozen importlib._bootstrap_external>", line 848, in exec_module
  File "<frozen importlib._bootstrap>", line 219, in _call_with_frames_removed
  File "/var/www/uwsgi/dashboard/dashboard_app/api_urls.py", line 19, in <module>
    path('password-reset/', views.password_reset_request, name='password_reset_request'),
AttributeError: module 'dashboard_app.views' has no attribute 'password_reset_request'
Performing system checks...

Exception in thread django-main-thread:
Traceback (most recent call last):
  File "/usr/lib/python3.8/threading.py", line 932, in _bootstrap_inner
    self.run()
  File "/usr/lib/python3.8/threading.py", line 870, in run
    self._target(*self._args, **self._kwargs)
  File "/var/www/uwsgi/dashboard/venv/lib/python3.8/site-packages/django/utils/autoreload.py", line 64, in wrapper
    fn(*args, **kwargs)
  File "/var/www/uwsgi/dashboard/venv/lib/python3.8/site-packages/django/core/management/commands/runserver.py", line 133, in inner_run
    self.check(display_num_errors=True)
  File "/var/www/uwsgi/dashboard/venv/lib/python3.8/site-packages/django/core/management/base.py", line 485, in check
    all_issues = checks.run_checks(
  File "/var/www/uwsgi/dashboard/venv/lib/python3.8/site-packages/django/core/checks/registry.py", line 88, in run_checks
    new_errors = check(app_configs=app_configs, databases=databases)
  File "/var/www/uwsgi/dashboard/venv/lib/python3.8/site-packages/django/core/checks/urls.py", line 14, in check_url_config
    return check_resolver(resolver)
  File "/var/www/uwsgi/dashboard/venv/lib/python3.8/site-packages/django/core/checks/urls.py", line 24, in check_resolver
    return check_method()
  File "/var/www/uwsgi/dashboard/venv/lib/python3.8/site-packages/django/urls/resolvers.py", line 494, in check
    for pattern in self.url_patterns:
  File "/var/www/uwsgi/dashboard/venv/lib/python3.8/site-packages/django/utils/functional.py", line 57, in __get__
    res = instance.__dict__[self.name] = self.func(instance)
  File "/var/www/uwsgi/dashboard/venv/lib/python3.8/site-packages/django/urls/resolvers.py", line 715, in url_patterns
    patterns = getattr(self.urlconf_module, "urlpatterns", self.urlconf_module)
  File "/var/www/uwsgi/dashboard/venv/lib/python3.8/site-packages/django/utils/functional.py", line 57, in __get__
    res = instance.__dict__[self.name] = self.func(instance)
  File "/var/www/uwsgi/dashboard/venv/lib/python3.8/site-packages/django/urls/resolvers.py", line 708, in urlconf_module
    return import_module(self.urlconf_name)
  File "/usr/lib/python3.8/importlib/__init__.py", line 127, in import_module
    return _bootstrap._gcd_import(name[level:], package, level)
  File "<frozen importlib._bootstrap>", line 1014, in _gcd_import
  File "<frozen importlib._bootstrap>", line 991, in _find_and_load
  File "<frozen importlib._bootstrap>", line 975, in _find_and_load_unlocked
  File "<frozen importlib._bootstrap>", line 671, in _load_unlocked
  File "<frozen importlib._bootstrap_external>", line 848, in exec_module
  File "<frozen importlib._bootstrap>", line 219, in _call_with_frames_removed
  File "/var/www/uwsgi/dashboard/dashboard/urls.py", line 23, in <module>
    path('api/', include('dashboard_app.api_urls')),
  File "/var/www/uwsgi/dashboard/venv/lib/python3.8/site-packages/django/urls/conf.py", line 38, in include
    urlconf_module = import_module(urlconf_module)
  File "/usr/lib/python3.8/importlib/__init__.py", line 127, in import_module
    return _bootstrap._gcd_import(name[level:], package, level)
  File "<frozen importlib._bootstrap>", line 1014, in _gcd_import
  File "<frozen importlib._bootstrap>", line 991, in _find_and_load
  File "<frozen importlib._bootstrap>", line 975, in _find_and_load_unlocked
  File "<frozen importlib._bootstrap>", line 671, in _load_unlocked
  File "<frozen importlib._bootstrap_external>", line 848, in exec_module
  File "<frozen importlib._bootstrap>", line 219, in _call_with_frames_removed
  File "/var/www/uwsgi/dashboard/dashboard_app/api_urls.py", line 19, in <module>
    path('password-reset/', views.password_reset_request, name='password_reset_request'),
AttributeError: module 'dashboard_app.views' has no attribute 'password_reset_request'
Exception in thread django-main-thread:
Traceback (most recent call last):
  File "/usr/lib/python3.8/threading.py", line 932, in _bootstrap_inner
    self.run()
  File "/usr/lib/python3.8/threading.py", line 870, in run
    self._target(*self._args, **self._kwargs)
  File "/var/www/uwsgi/dashboard/venv/lib/python3.8/site-packages/django/utils/autoreload.py", line 64, in wrapper
    fn(*args, **kwargs)
  File "/var/www/uwsgi/dashboard/venv/lib/python3.8/site-packages/django/core/management/commands/runserver.py", line 133, in inner_run
    self.check(display_num_errors=True)
  File "/var/www/uwsgi/dashboard/venv/lib/python3.8/site-packages/django/core/management/base.py", line 485, in check
    all_issues = checks.run_checks(
  File "/var/www/uwsgi/dashboard/venv/lib/python3.8/site-packages/django/core/checks/registry.py", line 88, in run_checks
    new_errors = check(app_configs=app_configs, databases=databases)
  File "/var/www/uwsgi/dashboard/venv/lib/python3.8/site-packages/django/core/checks/urls.py", line 14, in check_url_config
    return check_resolver(resolver)
  File "/var/www/uwsgi/dashboard/venv/lib/python3.8/site-packages/django/core/checks/urls.py", line 24, in check_resolver
    return check_method()
  File "/var/www/uwsgi/dashboard/venv/lib/python3.8/site-packages/django/urls/resolvers.py", line 494, in check
    for pattern in self.url_patterns:
  File "/var/www/uwsgi/dashboard/venv/lib/python3.8/site-packages/django/utils/functional.py", line 57, in __get__
    res = instance.__dict__[self.name] = self.func(instance)
  File "/var/www/uwsgi/dashboard/venv/lib/python3.8/site-packages/django/urls/resolvers.py", line 715, in url_patterns
    patterns = getattr(self.urlconf_module, "urlpatterns", self.urlconf_module)
  File "/var/www/uwsgi/dashboard/venv/lib/python3.8/site-packages/django/utils/functional.py", line 57, in __get__
    res = instance.__dict__[self.name] = self.func(instance)
  File "/var/www/uwsgi/dashboard/venv/lib/python3.8/site-packages/django/urls/resolvers.py", line 708, in urlconf_module
    return import_module(self.urlconf_name)
  File "/usr/lib/python3.8/importlib/__init__.py", line 127, in import_module
    return _bootstrap._gcd_import(name[level:], package, level)
  File "<frozen importlib._bootstrap>", line 1014, in _gcd_import
  File "<frozen importlib._bootstrap>", line 991, in _find_and_load
  File "<frozen importlib._bootstrap>", line 975, in _find_and_load_unlocked
  File "<frozen importlib._bootstrap>", line 671, in _load_unlocked
  File "<frozen importlib._bootstrap_external>", line 848, in exec_module
  File "<frozen importlib._bootstrap>", line 219, in _call_with_frames_removed
  File "/var/www/uwsgi/dashboard/dashboard/urls.py", line 23, in <module>
    path('api/', include('dashboard_app.api_urls')),
  File "/var/www/uwsgi/dashboard/venv/lib/python3.8/site-packages/django/urls/conf.py", line 38, in include
    urlconf_module = import_module(urlconf_module)
  File "/usr/lib/python3.8/importlib/__init__.py", line 127, in import_module
    return _bootstrap._gcd_import(name[level:], package, level)
  File "<frozen importlib._bootstrap>", line 1014, in _gcd_import
  File "<frozen importlib._bootstrap>", line 991, in _find_and_load
  File "<frozen importlib._bootstrap>", line 975, in _find_and_load_unlocked
  File "<frozen importlib._bootstrap>", line 671, in _load_unlocked
  File "<frozen importlib._bootstrap_external>", line 848, in exec_module
  File "<frozen importlib._bootstrap>", line 219, in _call_with_frames_removed
  File "/var/www/uwsgi/dashboard/dashboard_app/api_urls.py", line 19, in <module>
    path('password-reset/', views.password_reset_request, name='password_reset_request'),
AttributeError: module 'dashboard_app.views' has no attribute 'password_reset_request'
Performing system checks...

Exception in thread django-main-thread:
Traceback (most recent call last):
  File "/usr/lib/python3.8/threading.py", line 932, in _bootstrap_inner
    self.run()
  File "/usr/lib/python3.8/threading.py", line 870, in run
    self._target(*self._args, **self._kwargs)
  File "/var/www/uwsgi/dashboard/venv/lib/python3.8/site-packages/django/utils/autoreload.py", line 64, in wrapper
    fn(*args, **kwargs)
  File "/var/www/uwsgi/dashboard/venv/lib/python3.8/site-packages/django/core/management/commands/runserver.py", line 133, in inner_run
    self.check(display_num_errors=True)
  File "/var/www/uwsgi/dashboard/venv/lib/python3.8/site-packages/django/core/management/base.py", line 485, in check
    all_issues = checks.run_checks(
  File "/var/www/uwsgi/dashboard/venv/lib/python3.8/site-packages/django/core/checks/registry.py", line 88, in run_checks
    new_errors = check(app_configs=app_configs, databases=databases)
  File "/var/www/uwsgi/dashboard/venv/lib/python3.8/site-packages/django/core/checks/urls.py", line 14, in check_url_config
    return check_resolver(resolver)
  File "/var/www/uwsgi/dashboard/venv/lib/python3.8/site-packages/django/core/checks/urls.py", line 24, in check_resolver
    return check_method()
  File "/var/www/uwsgi/dashboard/venv/lib/python3.8/site-packages/django/urls/resolvers.py", line 494, in check
    for pattern in self.url_patterns:
  File "/var/www/uwsgi/dashboard/venv/lib/python3.8/site-packages/django/utils/functional.py", line 57, in __get__
    res = instance.__dict__[self.name] = self.func(instance)
  File "/var/www/uwsgi/dashboard/venv/lib/python3.8/site-packages/django/urls/resolvers.py", line 715, in url_patterns
    patterns = getattr(self.urlconf_module, "urlpatterns", self.urlconf_module)
  File "/var/www/uwsgi/dashboard/venv/lib/python3.8/site-packages/django/utils/functional.py", line 57, in __get__
    res = instance.__dict__[self.name] = self.func(instance)
  File "/var/www/uwsgi/dashboard/venv/lib/python3.8/site-packages/django/urls/resolvers.py", line 708, in urlconf_module
    return import_module(self.urlconf_name)
  File "/usr/lib/python3.8/importlib/__init__.py", line 127, in import_module
    return _bootstrap._gcd_import(name[level:], package, level)
  File "<frozen importlib._bootstrap>", line 1014, in _gcd_import
  File "<frozen importlib._bootstrap>", line 991, in _find_and_load
  File "<frozen importlib._bootstrap>", line 975, in _find_and_load_unlocked
  File "<frozen importlib._bootstrap>", line 671, in _load_unlocked
  File "<frozen importlib._bootstrap_external>", line 848, in exec_module
  File "<frozen importlib._bootstrap>", line 219, in _call_with_frames_removed
  File "/var/www/uwsgi/dashboard/dashboard/urls.py", line 23, in <module>
    path('api/', include('dashboard_app.api_urls')),
  File "/var/www/uwsgi/dashboard/venv/lib/python3.8/site-packages/django/urls/conf.py", line 38, in include
    urlconf_module = import_module(urlconf_module)
  File "/usr/lib/python3.8/importlib/__init__.py", line 127, in import_module
    return _bootstrap._gcd_import(name[level:], package, level)
  File "<frozen importlib._bootstrap>", line 1014, in _gcd_import
  File "<frozen importlib._bootstrap>", line 991, in _find_and_load
  File "<frozen importlib._bootstrap>", line 975, in _find_and_load_unlocked
  File "<frozen importlib._bootstrap>", line 671, in _load_unlocked
  File "<frozen importlib._bootstrap_external>", line 848, in exec_module
  File "<frozen importlib._bootstrap>", line 219, in _call_with_frames_removed
  File "/var/www/uwsgi/dashboard/dashboard_app/api_urls.py", line 19, in <module>
    path('password-reset/', views.password_reset_request, name='password_reset_request'),
AttributeError: module 'dashboard_app.views' has no attribute 'password_reset_request'
Performing system checks...

Performing system checks...

Exception in thread django-main-thread:
Traceback (most recent call last):
  File "/usr/lib/python3.8/threading.py", line 932, in _bootstrap_inner
    self.run()
  File "/usr/lib/python3.8/threading.py", line 870, in run
    self._target(*self._args, **self._kwargs)
  File "/var/www/uwsgi/dashboard/venv/lib/python3.8/site-packages/django/utils/autoreload.py", line 64, in wrapper
    fn(*args, **kwargs)
  File "/var/www/uwsgi/dashboard/venv/lib/python3.8/site-packages/django/core/management/commands/runserver.py", line 133, in inner_run
    self.check(display_num_errors=True)
  File "/var/www/uwsgi/dashboard/venv/lib/python3.8/site-packages/django/core/management/base.py", line 485, in check
    all_issues = checks.run_checks(
  File "/var/www/uwsgi/dashboard/venv/lib/python3.8/site-packages/django/core/checks/registry.py", line 88, in run_checks
    new_errors = check(app_configs=app_configs, databases=databases)
  File "/var/www/uwsgi/dashboard/venv/lib/python3.8/site-packages/django/core/checks/urls.py", line 14, in check_url_config
    return check_resolver(resolver)
  File "/var/www/uwsgi/dashboard/venv/lib/python3.8/site-packages/django/core/checks/urls.py", line 24, in check_resolver
    return check_method()
  File "/var/www/uwsgi/dashboard/venv/lib/python3.8/site-packages/django/urls/resolvers.py", line 494, in check
    for pattern in self.url_patterns:
  File "/var/www/uwsgi/dashboard/venv/lib/python3.8/site-packages/django/utils/functional.py", line 57, in __get__
    res = instance.__dict__[self.name] = self.func(instance)
  File "/var/www/uwsgi/dashboard/venv/lib/python3.8/site-packages/django/urls/resolvers.py", line 715, in url_patterns
    patterns = getattr(self.urlconf_module, "urlpatterns", self.urlconf_module)
  File "/var/www/uwsgi/dashboard/venv/lib/python3.8/site-packages/django/utils/functional.py", line 57, in __get__
    res = instance.__dict__[self.name] = self.func(instance)
  File "/var/www/uwsgi/dashboard/venv/lib/python3.8/site-packages/django/urls/resolvers.py", line 708, in urlconf_module
    return import_module(self.urlconf_name)
  File "/usr/lib/python3.8/importlib/__init__.py", line 127, in import_module
    return _bootstrap._gcd_import(name[level:], package, level)
  File "<frozen importlib._bootstrap>", line 1014, in _gcd_import
  File "<frozen importlib._bootstrap>", line 991, in _find_and_load
  File "<frozen importlib._bootstrap>", line 975, in _find_and_load_unlocked
  File "<frozen importlib._bootstrap>", line 671, in _load_unlocked
  File "<frozen importlib._bootstrap_external>", line 848, in exec_module
  File "<frozen importlib._bootstrap>", line 219, in _call_with_frames_removed
  File "/var/www/uwsgi/dashboard/dashboard/urls.py", line 23, in <module>
    path('api/', include('dashboard_app.api_urls')),
  File "/var/www/uwsgi/dashboard/venv/lib/python3.8/site-packages/django/urls/conf.py", line 38, in include
    urlconf_module = import_module(urlconf_module)
  File "/usr/lib/python3.8/importlib/__init__.py", line 127, in import_module
    return _bootstrap._gcd_import(name[level:], package, level)
  File "<frozen importlib._bootstrap>", line 1014, in _gcd_import
  File "<frozen importlib._bootstrap>", line 991, in _find_and_load
  File "<frozen importlib._bootstrap>", line 975, in _find_and_load_unlocked
  File "<frozen importlib._bootstrap>", line 671, in _load_unlocked
  File "<frozen importlib._bootstrap_external>", line 848, in exec_module
  File "<frozen importlib._bootstrap>", line 219, in _call_with_frames_removed
  File "/var/www/uwsgi/dashboard/dashboard_app/api_urls.py", line 19, in <module>
    path('password-reset/', views.password_reset_request, name='password_reset_request'),
AttributeError: module 'dashboard_app.views' has no attribute 'password_reset_request'
Exception in thread django-main-thread:
Traceback (most recent call last):
  File "/usr/lib/python3.8/threading.py", line 932, in _bootstrap_inner
    self.run()
  File "/usr/lib/python3.8/threading.py", line 870, in run
    self._target(*self._args, **self._kwargs)
  File "/var/www/uwsgi/dashboard/venv/lib/python3.8/site-packages/django/utils/autoreload.py", line 64, in wrapper
    fn(*args, **kwargs)
  File "/var/www/uwsgi/dashboard/venv/lib/python3.8/site-packages/django/core/management/commands/runserver.py", line 133, in inner_run
    self.check(display_num_errors=True)
  File "/var/www/uwsgi/dashboard/venv/lib/python3.8/site-packages/django/core/management/base.py", line 485, in check
    all_issues = checks.run_checks(
  File "/var/www/uwsgi/dashboard/venv/lib/python3.8/site-packages/django/core/checks/registry.py", line 88, in run_checks
    new_errors = check(app_configs=app_configs, databases=databases)
  File "/var/www/uwsgi/dashboard/venv/lib/python3.8/site-packages/django/core/checks/urls.py", line 14, in check_url_config
    return check_resolver(resolver)
  File "/var/www/uwsgi/dashboard/venv/lib/python3.8/site-packages/django/core/checks/urls.py", line 24, in check_resolver
    return check_method()
  File "/var/www/uwsgi/dashboard/venv/lib/python3.8/site-packages/django/urls/resolvers.py", line 494, in check
    for pattern in self.url_patterns:
  File "/var/www/uwsgi/dashboard/venv/lib/python3.8/site-packages/django/utils/functional.py", line 57, in __get__
    res = instance.__dict__[self.name] = self.func(instance)
  File "/var/www/uwsgi/dashboard/venv/lib/python3.8/site-packages/django/urls/resolvers.py", line 715, in url_patterns
    patterns = getattr(self.urlconf_module, "urlpatterns", self.urlconf_module)
  File "/var/www/uwsgi/dashboard/venv/lib/python3.8/site-packages/django/utils/functional.py", line 57, in __get__
    res = instance.__dict__[self.name] = self.func(instance)
  File "/var/www/uwsgi/dashboard/venv/lib/python3.8/site-packages/django/urls/resolvers.py", line 708, in urlconf_module
    return import_module(self.urlconf_name)
  File "/usr/lib/python3.8/importlib/__init__.py", line 127, in import_module
    return _bootstrap._gcd_import(name[level:], package, level)
  File "<frozen importlib._bootstrap>", line 1014, in _gcd_import
  File "<frozen importlib._bootstrap>", line 991, in _find_and_load
  File "<frozen importlib._bootstrap>", line 975, in _find_and_load_unlocked
  File "<frozen importlib._bootstrap>", line 671, in _load_unlocked
  File "<frozen importlib._bootstrap_external>", line 848, in exec_module
  File "<frozen importlib._bootstrap>", line 219, in _call_with_frames_removed
  File "/var/www/uwsgi/dashboard/dashboard/urls.py", line 23, in <module>
    path('api/', include('dashboard_app.api_urls')),
  File "/var/www/uwsgi/dashboard/venv/lib/python3.8/site-packages/django/urls/conf.py", line 38, in include
    urlconf_module = import_module(urlconf_module)
  File "/usr/lib/python3.8/importlib/__init__.py", line 127, in import_module
    return _bootstrap._gcd_import(name[level:], package, level)
  File "<frozen importlib._bootstrap>", line 1014, in _gcd_import
  File "<frozen importlib._bootstrap>", line 991, in _find_and_load
  File "<frozen importlib._bootstrap>", line 975, in _find_and_load_unlocked
  File "<frozen importlib._bootstrap>", line 671, in _load_unlocked
  File "<frozen importlib._bootstrap_external>", line 848, in exec_module
  File "<frozen importlib._bootstrap>", line 219, in _call_with_frames_removed
  File "/var/www/uwsgi/dashboard/dashboard_app/api_urls.py", line 19, in <module>
    path('password-reset/', views.password_reset_request, name='password_reset_request'),
AttributeError: module 'dashboard_app.views' has no attribute 'password_reset_request'
Performing system checks...

Performing system checks...

Performing system checks...

Exception in thread django-main-thread:
Traceback (most recent call last):
  File "/usr/lib/python3.8/threading.py", line 932, in _bootstrap_inner
    self.run()
  File "/usr/lib/python3.8/threading.py", line 870, in run
    self._target(*self._args, **self._kwargs)
  File "/var/www/uwsgi/dashboard/venv/lib/python3.8/site-packages/django/utils/autoreload.py", line 64, in wrapper
    fn(*args, **kwargs)
  File "/var/www/uwsgi/dashboard/venv/lib/python3.8/site-packages/django/core/management/commands/runserver.py", line 133, in inner_run
    self.check(display_num_errors=True)
  File "/var/www/uwsgi/dashboard/venv/lib/python3.8/site-packages/django/core/management/base.py", line 485, in check
    all_issues = checks.run_checks(
  File "/var/www/uwsgi/dashboard/venv/lib/python3.8/site-packages/django/core/checks/registry.py", line 88, in run_checks
    new_errors = check(app_configs=app_configs, databases=databases)
  File "/var/www/uwsgi/dashboard/venv/lib/python3.8/site-packages/django/core/checks/urls.py", line 14, in check_url_config
    return check_resolver(resolver)
  File "/var/www/uwsgi/dashboard/venv/lib/python3.8/site-packages/django/core/checks/urls.py", line 24, in check_resolver
    return check_method()
  File "/var/www/uwsgi/dashboard/venv/lib/python3.8/site-packages/django/urls/resolvers.py", line 494, in check
    for pattern in self.url_patterns:
  File "/var/www/uwsgi/dashboard/venv/lib/python3.8/site-packages/django/utils/functional.py", line 57, in __get__
    res = instance.__dict__[self.name] = self.func(instance)
  File "/var/www/uwsgi/dashboard/venv/lib/python3.8/site-packages/django/urls/resolvers.py", line 715, in url_patterns
    patterns = getattr(self.urlconf_module, "urlpatterns", self.urlconf_module)
  File "/var/www/uwsgi/dashboard/venv/lib/python3.8/site-packages/django/utils/functional.py", line 57, in __get__
    res = instance.__dict__[self.name] = self.func(instance)
  File "/var/www/uwsgi/dashboard/venv/lib/python3.8/site-packages/django/urls/resolvers.py", line 708, in urlconf_module
    return import_module(self.urlconf_name)
  File "/usr/lib/python3.8/importlib/__init__.py", line 127, in import_module
    return _bootstrap._gcd_import(name[level:], package, level)
  File "<frozen importlib._bootstrap>", line 1014, in _gcd_import
  File "<frozen importlib._bootstrap>", line 991, in _find_and_load
  File "<frozen importlib._bootstrap>", line 975, in _find_and_load_unlocked
  File "<frozen importlib._bootstrap>", line 671, in _load_unlocked
  File "<frozen importlib._bootstrap_external>", line 848, in exec_module
  File "<frozen importlib._bootstrap>", line 219, in _call_with_frames_removed
  File "/var/www/uwsgi/dashboard/dashboard/urls.py", line 23, in <module>
    path('api/', include('dashboard_app.api_urls')),
  File "/var/www/uwsgi/dashboard/venv/lib/python3.8/site-packages/django/urls/conf.py", line 38, in include
    urlconf_module = import_module(urlconf_module)
  File "/usr/lib/python3.8/importlib/__init__.py", line 127, in import_module
    return _bootstrap._gcd_import(name[level:], package, level)
  File "<frozen importlib._bootstrap>", line 1014, in _gcd_import
  File "<frozen importlib._bootstrap>", line 991, in _find_and_load
  File "<frozen importlib._bootstrap>", line 975, in _find_and_load_unlocked
  File "<frozen importlib._bootstrap>", line 671, in _load_unlocked
  File "<frozen importlib._bootstrap_external>", line 848, in exec_module
  File "<frozen importlib._bootstrap>", line 219, in _call_with_frames_removed
  File "/var/www/uwsgi/dashboard/dashboard_app/api_urls.py", line 19, in <module>
    path('password-reset/', views.password_reset_request, name='password_reset_request'),
AttributeError: module 'dashboard_app.views' has no attribute 'password_reset_request'
Exception in thread django-main-thread:
Traceback (most recent call last):
  File "/usr/lib/python3.8/threading.py", line 932, in _bootstrap_inner
    self.run()
  File "/usr/lib/python3.8/threading.py", line 870, in run
    self._target(*self._args, **self._kwargs)
  File "/var/www/uwsgi/dashboard/venv/lib/python3.8/site-packages/django/utils/autoreload.py", line 64, in wrapper
    fn(*args, **kwargs)
  File "/var/www/uwsgi/dashboard/venv/lib/python3.8/site-packages/django/core/management/commands/runserver.py", line 133, in inner_run
    self.check(display_num_errors=True)
  File "/var/www/uwsgi/dashboard/venv/lib/python3.8/site-packages/django/core/management/base.py", line 485, in check
    all_issues = checks.run_checks(
  File "/var/www/uwsgi/dashboard/venv/lib/python3.8/site-packages/django/core/checks/registry.py", line 88, in run_checks
    new_errors = check(app_configs=app_configs, databases=databases)
  File "/var/www/uwsgi/dashboard/venv/lib/python3.8/site-packages/django/core/checks/urls.py", line 14, in check_url_config
    return check_resolver(resolver)
  File "/var/www/uwsgi/dashboard/venv/lib/python3.8/site-packages/django/core/checks/urls.py", line 24, in check_resolver
    return check_method()
  File "/var/www/uwsgi/dashboard/venv/lib/python3.8/site-packages/django/urls/resolvers.py", line 494, in check
    for pattern in self.url_patterns:
  File "/var/www/uwsgi/dashboard/venv/lib/python3.8/site-packages/django/utils/functional.py", line 57, in __get__
    res = instance.__dict__[self.name] = self.func(instance)
  File "/var/www/uwsgi/dashboard/venv/lib/python3.8/site-packages/django/urls/resolvers.py", line 715, in url_patterns
    patterns = getattr(self.urlconf_module, "urlpatterns", self.urlconf_module)
  File "/var/www/uwsgi/dashboard/venv/lib/python3.8/site-packages/django/utils/functional.py", line 57, in __get__
    res = instance.__dict__[self.name] = self.func(instance)
  File "/var/www/uwsgi/dashboard/venv/lib/python3.8/site-packages/django/urls/resolvers.py", line 708, in urlconf_module
    return import_module(self.urlconf_name)
  File "/usr/lib/python3.8/importlib/__init__.py", line 127, in import_module
    return _bootstrap._gcd_import(name[level:], package, level)
  File "<frozen importlib._bootstrap>", line 1014, in _gcd_import
  File "<frozen importlib._bootstrap>", line 991, in _find_and_load
  File "<frozen importlib._bootstrap>", line 975, in _find_and_load_unlocked
  File "<frozen importlib._bootstrap>", line 671, in _load_unlocked
  File "<frozen importlib._bootstrap_external>", line 848, in exec_module
  File "<frozen importlib._bootstrap>", line 219, in _call_with_frames_removed
  File "/var/www/uwsgi/dashboard/dashboard/urls.py", line 23, in <module>
    path('api/', include('dashboard_app.api_urls')),
  File "/var/www/uwsgi/dashboard/venv/lib/python3.8/site-packages/django/urls/conf.py", line 38, in include
    urlconf_module = import_module(urlconf_module)
  File "/usr/lib/python3.8/importlib/__init__.py", line 127, in import_module
    return _bootstrap._gcd_import(name[level:], package, level)
  File "<frozen importlib._bootstrap>", line 1014, in _gcd_import
  File "<frozen importlib._bootstrap>", line 991, in _find_and_load
  File "<frozen importlib._bootstrap>", line 975, in _find_and_load_unlocked
  File "<frozen importlib._bootstrap>", line 671, in _load_unlocked
  File "<frozen importlib._bootstrap_external>", line 848, in exec_module
  File "<frozen importlib._bootstrap>", line 219, in _call_with_frames_removed
  File "/var/www/uwsgi/dashboard/dashboard_app/api_urls.py", line 19, in <module>
    path('password-reset/', views.password_reset_request, name='password_reset_request'),
AttributeError: module 'dashboard_app.views' has no attribute 'password_reset_request'
Exception in thread django-main-thread:
Traceback (most recent call last):
  File "/usr/lib/python3.8/threading.py", line 932, in _bootstrap_inner
    self.run()
  File "/usr/lib/python3.8/threading.py", line 870, in run
    self._target(*self._args, **self._kwargs)
  File "/var/www/uwsgi/dashboard/venv/lib/python3.8/site-packages/django/utils/autoreload.py", line 64, in wrapper
    fn(*args, **kwargs)
  File "/var/www/uwsgi/dashboard/venv/lib/python3.8/site-packages/django/core/management/commands/runserver.py", line 133, in inner_run
    self.check(display_num_errors=True)
  File "/var/www/uwsgi/dashboard/venv/lib/python3.8/site-packages/django/core/management/base.py", line 485, in check
    all_issues = checks.run_checks(
  File "/var/www/uwsgi/dashboard/venv/lib/python3.8/site-packages/django/core/checks/registry.py", line 88, in run_checks
    new_errors = check(app_configs=app_configs, databases=databases)
  File "/var/www/uwsgi/dashboard/venv/lib/python3.8/site-packages/django/core/checks/urls.py", line 14, in check_url_config
    return check_resolver(resolver)
  File "/var/www/uwsgi/dashboard/venv/lib/python3.8/site-packages/django/core/checks/urls.py", line 24, in check_resolver
    return check_method()
  File "/var/www/uwsgi/dashboard/venv/lib/python3.8/site-packages/django/urls/resolvers.py", line 494, in check
    for pattern in self.url_patterns:
  File "/var/www/uwsgi/dashboard/venv/lib/python3.8/site-packages/django/utils/functional.py", line 57, in __get__
    res = instance.__dict__[self.name] = self.func(instance)
  File "/var/www/uwsgi/dashboard/venv/lib/python3.8/site-packages/django/urls/resolvers.py", line 715, in url_patterns
    patterns = getattr(self.urlconf_module, "urlpatterns", self.urlconf_module)
  File "/var/www/uwsgi/dashboard/venv/lib/python3.8/site-packages/django/utils/functional.py", line 57, in __get__
    res = instance.__dict__[self.name] = self.func(instance)
  File "/var/www/uwsgi/dashboard/venv/lib/python3.8/site-packages/django/urls/resolvers.py", line 708, in urlconf_module
    return import_module(self.urlconf_name)
  File "/usr/lib/python3.8/importlib/__init__.py", line 127, in import_module
    return _bootstrap._gcd_import(name[level:], package, level)
  File "<frozen importlib._bootstrap>", line 1014, in _gcd_import
  File "<frozen importlib._bootstrap>", line 991, in _find_and_load
  File "<frozen importlib._bootstrap>", line 975, in _find_and_load_unlocked
  File "<frozen importlib._bootstrap>", line 671, in _load_unlocked
  File "<frozen importlib._bootstrap_external>", line 848, in exec_module
  File "<frozen importlib._bootstrap>", line 219, in _call_with_frames_removed
  File "/var/www/uwsgi/dashboard/dashboard/urls.py", line 23, in <module>
    path('api/', include('dashboard_app.api_urls')),
  File "/var/www/uwsgi/dashboard/venv/lib/python3.8/site-packages/django/urls/conf.py", line 38, in include
    urlconf_module = import_module(urlconf_module)
  File "/usr/lib/python3.8/importlib/__init__.py", line 127, in import_module
    return _bootstrap._gcd_import(name[level:], package, level)
  File "<frozen importlib._bootstrap>", line 1014, in _gcd_import
  File "<frozen importlib._bootstrap>", line 991, in _find_and_load
  File "<frozen importlib._bootstrap>", line 975, in _find_and_load_unlocked
  File "<frozen importlib._bootstrap>", line 671, in _load_unlocked
  File "<frozen importlib._bootstrap_external>", line 848, in exec_module
  File "<frozen importlib._bootstrap>", line 219, in _call_with_frames_removed
  File "/var/www/uwsgi/dashboard/dashboard_app/api_urls.py", line 19, in <module>
    path('password-reset/', views.password_reset_request, name='password_reset_request'),
AttributeError: module 'dashboard_app.views' has no attribute 'password_reset_request'
Performing system checks...

Performing system checks...

Performing system checks...

Exception in thread django-main-thread:
Traceback (most recent call last):
  File "/usr/lib/python3.8/threading.py", line 932, in _bootstrap_inner
    self.run()
  File "/usr/lib/python3.8/threading.py", line 870, in run
    self._target(*self._args, **self._kwargs)
  File "/var/www/uwsgi/dashboard/venv/lib/python3.8/site-packages/django/utils/autoreload.py", line 64, in wrapper
    fn(*args, **kwargs)
  File "/var/www/uwsgi/dashboard/venv/lib/python3.8/site-packages/django/core/management/commands/runserver.py", line 133, in inner_run
    self.check(display_num_errors=True)
  File "/var/www/uwsgi/dashboard/venv/lib/python3.8/site-packages/django/core/management/base.py", line 485, in check
    all_issues = checks.run_checks(
  File "/var/www/uwsgi/dashboard/venv/lib/python3.8/site-packages/django/core/checks/registry.py", line 88, in run_checks
    new_errors = check(app_configs=app_configs, databases=databases)
  File "/var/www/uwsgi/dashboard/venv/lib/python3.8/site-packages/django/core/checks/urls.py", line 14, in check_url_config
    return check_resolver(resolver)
  File "/var/www/uwsgi/dashboard/venv/lib/python3.8/site-packages/django/core/checks/urls.py", line 24, in check_resolver
    return check_method()
  File "/var/www/uwsgi/dashboard/venv/lib/python3.8/site-packages/django/urls/resolvers.py", line 494, in check
    for pattern in self.url_patterns:
  File "/var/www/uwsgi/dashboard/venv/lib/python3.8/site-packages/django/utils/functional.py", line 57, in __get__
    res = instance.__dict__[self.name] = self.func(instance)
  File "/var/www/uwsgi/dashboard/venv/lib/python3.8/site-packages/django/urls/resolvers.py", line 715, in url_patterns
    patterns = getattr(self.urlconf_module, "urlpatterns", self.urlconf_module)
  File "/var/www/uwsgi/dashboard/venv/lib/python3.8/site-packages/django/utils/functional.py", line 57, in __get__
    res = instance.__dict__[self.name] = self.func(instance)
  File "/var/www/uwsgi/dashboard/venv/lib/python3.8/site-packages/django/urls/resolvers.py", line 708, in urlconf_module
    return import_module(self.urlconf_name)
  File "/usr/lib/python3.8/importlib/__init__.py", line 127, in import_module
    return _bootstrap._gcd_import(name[level:], package, level)
  File "<frozen importlib._bootstrap>", line 1014, in _gcd_import
  File "<frozen importlib._bootstrap>", line 991, in _find_and_load
  File "<frozen importlib._bootstrap>", line 975, in _find_and_load_unlocked
  File "<frozen importlib._bootstrap>", line 671, in _load_unlocked
  File "<frozen importlib._bootstrap_external>", line 848, in exec_module
  File "<frozen importlib._bootstrap>", line 219, in _call_with_frames_removed
  File "/var/www/uwsgi/dashboard/dashboard/urls.py", line 23, in <module>
    path('api/', include('dashboard_app.api_urls')),
  File "/var/www/uwsgi/dashboard/venv/lib/python3.8/site-packages/django/urls/conf.py", line 38, in include
    urlconf_module = import_module(urlconf_module)
  File "/usr/lib/python3.8/importlib/__init__.py", line 127, in import_module
    return _bootstrap._gcd_import(name[level:], package, level)
  File "<frozen importlib._bootstrap>", line 1014, in _gcd_import
  File "<frozen importlib._bootstrap>", line 991, in _find_and_load
  File "<frozen importlib._bootstrap>", line 975, in _find_and_load_unlocked
  File "<frozen importlib._bootstrap>", line 671, in _load_unlocked
  File "<frozen importlib._bootstrap_external>", line 848, in exec_module
  File "<frozen importlib._bootstrap>", line 219, in _call_with_frames_removed
  File "/var/www/uwsgi/dashboard/dashboard_app/api_urls.py", line 19, in <module>
    path('password-reset/', views.password_reset_request, name='password_reset_request'),
AttributeError: module 'dashboard_app.views' has no attribute 'password_reset_request'
Exception in thread django-main-thread:
Traceback (most recent call last):
  File "/usr/lib/python3.8/threading.py", line 932, in _bootstrap_inner
    self.run()
  File "/usr/lib/python3.8/threading.py", line 870, in run
    self._target(*self._args, **self._kwargs)
  File "/var/www/uwsgi/dashboard/venv/lib/python3.8/site-packages/django/utils/autoreload.py", line 64, in wrapper
    fn(*args, **kwargs)
  File "/var/www/uwsgi/dashboard/venv/lib/python3.8/site-packages/django/core/management/commands/runserver.py", line 133, in inner_run
    self.check(display_num_errors=True)
  File "/var/www/uwsgi/dashboard/venv/lib/python3.8/site-packages/django/core/management/base.py", line 485, in check
    all_issues = checks.run_checks(
  File "/var/www/uwsgi/dashboard/venv/lib/python3.8/site-packages/django/core/checks/registry.py", line 88, in run_checks
    new_errors = check(app_configs=app_configs, databases=databases)
  File "/var/www/uwsgi/dashboard/venv/lib/python3.8/site-packages/django/core/checks/urls.py", line 14, in check_url_config
    return check_resolver(resolver)
  File "/var/www/uwsgi/dashboard/venv/lib/python3.8/site-packages/django/core/checks/urls.py", line 24, in check_resolver
    return check_method()
  File "/var/www/uwsgi/dashboard/venv/lib/python3.8/site-packages/django/urls/resolvers.py", line 494, in check
    for pattern in self.url_patterns:
  File "/var/www/uwsgi/dashboard/venv/lib/python3.8/site-packages/django/utils/functional.py", line 57, in __get__
    res = instance.__dict__[self.name] = self.func(instance)
  File "/var/www/uwsgi/dashboard/venv/lib/python3.8/site-packages/django/urls/resolvers.py", line 715, in url_patterns
    patterns = getattr(self.urlconf_module, "urlpatterns", self.urlconf_module)
  File "/var/www/uwsgi/dashboard/venv/lib/python3.8/site-packages/django/utils/functional.py", line 57, in __get__
    res = instance.__dict__[self.name] = self.func(instance)
  File "/var/www/uwsgi/dashboard/venv/lib/python3.8/site-packages/django/urls/resolvers.py", line 708, in urlconf_module
    return import_module(self.urlconf_name)
  File "/usr/lib/python3.8/importlib/__init__.py", line 127, in import_module
    return _bootstrap._gcd_import(name[level:], package, level)
  File "<frozen importlib._bootstrap>", line 1014, in _gcd_import
  File "<frozen importlib._bootstrap>", line 991, in _find_and_load
  File "<frozen importlib._bootstrap>", line 975, in _find_and_load_unlocked
  File "<frozen importlib._bootstrap>", line 671, in _load_unlocked
  File "<frozen importlib._bootstrap_external>", line 848, in exec_module
  File "<frozen importlib._bootstrap>", line 219, in _call_with_frames_removed
  File "/var/www/uwsgi/dashboard/dashboard/urls.py", line 23, in <module>
    path('api/', include('dashboard_app.api_urls')),
  File "/var/www/uwsgi/dashboard/venv/lib/python3.8/site-packages/django/urls/conf.py", line 38, in include
    urlconf_module = import_module(urlconf_module)
  File "/usr/lib/python3.8/importlib/__init__.py", line 127, in import_module
    return _bootstrap._gcd_import(name[level:], package, level)
  File "<frozen importlib._bootstrap>", line 1014, in _gcd_import
  File "<frozen importlib._bootstrap>", line 991, in _find_and_load
  File "<frozen importlib._bootstrap>", line 975, in _find_and_load_unlocked
  File "<frozen importlib._bootstrap>", line 671, in _load_unlocked
  File "<frozen importlib._bootstrap_external>", line 848, in exec_module
  File "<frozen importlib._bootstrap>", line 219, in _call_with_frames_removed
  File "/var/www/uwsgi/dashboard/dashboard_app/api_urls.py", line 19, in <module>
    path('password-reset/', views.password_reset_request, name='password_reset_request'),
AttributeError: module 'dashboard_app.views' has no attribute 'password_reset_request'
Exception in thread django-main-thread:
Traceback (most recent call last):
  File "/usr/lib/python3.8/threading.py", line 932, in _bootstrap_inner
    self.run()
  File "/usr/lib/python3.8/threading.py", line 870, in run
    self._target(*self._args, **self._kwargs)
  File "/var/www/uwsgi/dashboard/venv/lib/python3.8/site-packages/django/utils/autoreload.py", line 64, in wrapper
    fn(*args, **kwargs)
  File "/var/www/uwsgi/dashboard/venv/lib/python3.8/site-packages/django/core/management/commands/runserver.py", line 133, in inner_run
    self.check(display_num_errors=True)
  File "/var/www/uwsgi/dashboard/venv/lib/python3.8/site-packages/django/core/management/base.py", line 485, in check
    all_issues = checks.run_checks(
  File "/var/www/uwsgi/dashboard/venv/lib/python3.8/site-packages/django/core/checks/registry.py", line 88, in run_checks
    new_errors = check(app_configs=app_configs, databases=databases)
  File "/var/www/uwsgi/dashboard/venv/lib/python3.8/site-packages/django/core/checks/urls.py", line 14, in check_url_config
    return check_resolver(resolver)
  File "/var/www/uwsgi/dashboard/venv/lib/python3.8/site-packages/django/core/checks/urls.py", line 24, in check_resolver
    return check_method()
  File "/var/www/uwsgi/dashboard/venv/lib/python3.8/site-packages/django/urls/resolvers.py", line 494, in check
    for pattern in self.url_patterns:
  File "/var/www/uwsgi/dashboard/venv/lib/python3.8/site-packages/django/utils/functional.py", line 57, in __get__
    res = instance.__dict__[self.name] = self.func(instance)
  File "/var/www/uwsgi/dashboard/venv/lib/python3.8/site-packages/django/urls/resolvers.py", line 715, in url_patterns
    patterns = getattr(self.urlconf_module, "urlpatterns", self.urlconf_module)
  File "/var/www/uwsgi/dashboard/venv/lib/python3.8/site-packages/django/utils/functional.py", line 57, in __get__
    res = instance.__dict__[self.name] = self.func(instance)
  File "/var/www/uwsgi/dashboard/venv/lib/python3.8/site-packages/django/urls/resolvers.py", line 708, in urlconf_module
    return import_module(self.urlconf_name)
  File "/usr/lib/python3.8/importlib/__init__.py", line 127, in import_module
    return _bootstrap._gcd_import(name[level:], package, level)
  File "<frozen importlib._bootstrap>", line 1014, in _gcd_import
  File "<frozen importlib._bootstrap>", line 991, in _find_and_load
  File "<frozen importlib._bootstrap>", line 975, in _find_and_load_unlocked
  File "<frozen importlib._bootstrap>", line 671, in _load_unlocked
  File "<frozen importlib._bootstrap_external>", line 848, in exec_module
  File "<frozen importlib._bootstrap>", line 219, in _call_with_frames_removed
  File "/var/www/uwsgi/dashboard/dashboard/urls.py", line 23, in <module>
    path('api/', include('dashboard_app.api_urls')),
  File "/var/www/uwsgi/dashboard/venv/lib/python3.8/site-packages/django/urls/conf.py", line 38, in include
    urlconf_module = import_module(urlconf_module)
  File "/usr/lib/python3.8/importlib/__init__.py", line 127, in import_module
    return _bootstrap._gcd_import(name[level:], package, level)
  File "<frozen importlib._bootstrap>", line 1014, in _gcd_import
  File "<frozen importlib._bootstrap>", line 991, in _find_and_load
  File "<frozen importlib._bootstrap>", line 975, in _find_and_load_unlocked
  File "<frozen importlib._bootstrap>", line 671, in _load_unlocked
  File "<frozen importlib._bootstrap_external>", line 848, in exec_module
  File "<frozen importlib._bootstrap>", line 219, in _call_with_frames_removed
  File "/var/www/uwsgi/dashboard/dashboard_app/api_urls.py", line 19, in <module>
    path('password-reset/', views.password_reset_request, name='password_reset_request'),
AttributeError: module 'dashboard_app.views' has no attribute 'password_reset_request'
Performing system checks...

Performing system checks...

Performing system checks...

Exception in thread django-main-thread:
Traceback (most recent call last):
  File "/usr/lib/python3.8/threading.py", line 932, in _bootstrap_inner
    self.run()
  File "/usr/lib/python3.8/threading.py", line 870, in run
    self._target(*self._args, **self._kwargs)
  File "/var/www/uwsgi/dashboard/venv/lib/python3.8/site-packages/django/utils/autoreload.py", line 64, in wrapper
    fn(*args, **kwargs)
  File "/var/www/uwsgi/dashboard/venv/lib/python3.8/site-packages/django/core/management/commands/runserver.py", line 133, in inner_run
    self.check(display_num_errors=True)
  File "/var/www/uwsgi/dashboard/venv/lib/python3.8/site-packages/django/core/management/base.py", line 485, in check
    all_issues = checks.run_checks(
  File "/var/www/uwsgi/dashboard/venv/lib/python3.8/site-packages/django/core/checks/registry.py", line 88, in run_checks
    new_errors = check(app_configs=app_configs, databases=databases)
  File "/var/www/uwsgi/dashboard/venv/lib/python3.8/site-packages/django/core/checks/urls.py", line 14, in check_url_config
    return check_resolver(resolver)
  File "/var/www/uwsgi/dashboard/venv/lib/python3.8/site-packages/django/core/checks/urls.py", line 24, in check_resolver
    return check_method()
  File "/var/www/uwsgi/dashboard/venv/lib/python3.8/site-packages/django/urls/resolvers.py", line 494, in check
    for pattern in self.url_patterns:
  File "/var/www/uwsgi/dashboard/venv/lib/python3.8/site-packages/django/utils/functional.py", line 57, in __get__
    res = instance.__dict__[self.name] = self.func(instance)
  File "/var/www/uwsgi/dashboard/venv/lib/python3.8/site-packages/django/urls/resolvers.py", line 715, in url_patterns
    patterns = getattr(self.urlconf_module, "urlpatterns", self.urlconf_module)
  File "/var/www/uwsgi/dashboard/venv/lib/python3.8/site-packages/django/utils/functional.py", line 57, in __get__
    res = instance.__dict__[self.name] = self.func(instance)
  File "/var/www/uwsgi/dashboard/venv/lib/python3.8/site-packages/django/urls/resolvers.py", line 708, in urlconf_module
    return import_module(self.urlconf_name)
  File "/usr/lib/python3.8/importlib/__init__.py", line 127, in import_module
    return _bootstrap._gcd_import(name[level:], package, level)
  File "<frozen importlib._bootstrap>", line 1014, in _gcd_import
  File "<frozen importlib._bootstrap>", line 991, in _find_and_load
  File "<frozen importlib._bootstrap>", line 975, in _find_and_load_unlocked
  File "<frozen importlib._bootstrap>", line 671, in _load_unlocked
  File "<frozen importlib._bootstrap_external>", line 848, in exec_module
  File "<frozen importlib._bootstrap>", line 219, in _call_with_frames_removed
  File "/var/www/uwsgi/dashboard/dashboard/urls.py", line 23, in <module>
    path('api/', include('dashboard_app.api_urls')),
  File "/var/www/uwsgi/dashboard/venv/lib/python3.8/site-packages/django/urls/conf.py", line 38, in include
    urlconf_module = import_module(urlconf_module)
  File "/usr/lib/python3.8/importlib/__init__.py", line 127, in import_module
    return _bootstrap._gcd_import(name[level:], package, level)
  File "<frozen importlib._bootstrap>", line 1014, in _gcd_import
  File "<frozen importlib._bootstrap>", line 991, in _find_and_load
  File "<frozen importlib._bootstrap>", line 975, in _find_and_load_unlocked
  File "<frozen importlib._bootstrap>", line 671, in _load_unlocked
  File "<frozen importlib._bootstrap_external>", line 848, in exec_module
  File "<frozen importlib._bootstrap>", line 219, in _call_with_frames_removed
  File "/var/www/uwsgi/dashboard/dashboard_app/api_urls.py", line 19, in <module>
    path('password-reset/', views.password_reset_request, name='password_reset_request'),
AttributeError: module 'dashboard_app.views' has no attribute 'password_reset_request'
Exception in thread django-main-thread:
Traceback (most recent call last):
  File "/usr/lib/python3.8/threading.py", line 932, in _bootstrap_inner
    self.run()
  File "/usr/lib/python3.8/threading.py", line 870, in run
    self._target(*self._args, **self._kwargs)
  File "/var/www/uwsgi/dashboard/venv/lib/python3.8/site-packages/django/utils/autoreload.py", line 64, in wrapper
    fn(*args, **kwargs)
  File "/var/www/uwsgi/dashboard/venv/lib/python3.8/site-packages/django/core/management/commands/runserver.py", line 133, in inner_run
    self.check(display_num_errors=True)
  File "/var/www/uwsgi/dashboard/venv/lib/python3.8/site-packages/django/core/management/base.py", line 485, in check
    all_issues = checks.run_checks(
  File "/var/www/uwsgi/dashboard/venv/lib/python3.8/site-packages/django/core/checks/registry.py", line 88, in run_checks
    new_errors = check(app_configs=app_configs, databases=databases)
  File "/var/www/uwsgi/dashboard/venv/lib/python3.8/site-packages/django/core/checks/urls.py", line 14, in check_url_config
    return check_resolver(resolver)
  File "/var/www/uwsgi/dashboard/venv/lib/python3.8/site-packages/django/core/checks/urls.py", line 24, in check_resolver
    return check_method()
  File "/var/www/uwsgi/dashboard/venv/lib/python3.8/site-packages/django/urls/resolvers.py", line 494, in check
    for pattern in self.url_patterns:
  File "/var/www/uwsgi/dashboard/venv/lib/python3.8/site-packages/django/utils/functional.py", line 57, in __get__
    res = instance.__dict__[self.name] = self.func(instance)
  File "/var/www/uwsgi/dashboard/venv/lib/python3.8/site-packages/django/urls/resolvers.py", line 715, in url_patterns
    patterns = getattr(self.urlconf_module, "urlpatterns", self.urlconf_module)
  File "/var/www/uwsgi/dashboard/venv/lib/python3.8/site-packages/django/utils/functional.py", line 57, in __get__
    res = instance.__dict__[self.name] = self.func(instance)
  File "/var/www/uwsgi/dashboard/venv/lib/python3.8/site-packages/django/urls/resolvers.py", line 708, in urlconf_module
    return import_module(self.urlconf_name)
  File "/usr/lib/python3.8/importlib/__init__.py", line 127, in import_module
    return _bootstrap._gcd_import(name[level:], package, level)
  File "<frozen importlib._bootstrap>", line 1014, in _gcd_import
  File "<frozen importlib._bootstrap>", line 991, in _find_and_load
  File "<frozen importlib._bootstrap>", line 975, in _find_and_load_unlocked
  File "<frozen importlib._bootstrap>", line 671, in _load_unlocked
  File "<frozen importlib._bootstrap_external>", line 848, in exec_module
  File "<frozen importlib._bootstrap>", line 219, in _call_with_frames_removed
  File "/var/www/uwsgi/dashboard/dashboard/urls.py", line 23, in <module>
    path('api/', include('dashboard_app.api_urls')),
  File "/var/www/uwsgi/dashboard/venv/lib/python3.8/site-packages/django/urls/conf.py", line 38, in include
    urlconf_module = import_module(urlconf_module)
  File "/usr/lib/python3.8/importlib/__init__.py", line 127, in import_module
    return _bootstrap._gcd_import(name[level:], package, level)
  File "<frozen importlib._bootstrap>", line 1014, in _gcd_import
  File "<frozen importlib._bootstrap>", line 991, in _find_and_load
  File "<frozen importlib._bootstrap>", line 975, in _find_and_load_unlocked
  File "<frozen importlib._bootstrap>", line 671, in _load_unlocked
  File "<frozen importlib._bootstrap_external>", line 848, in exec_module
  File "<frozen importlib._bootstrap>", line 219, in _call_with_frames_removed
  File "/var/www/uwsgi/dashboard/dashboard_app/api_urls.py", line 19, in <module>
    path('password-reset/', views.password_reset_request, name='password_reset_request'),
AttributeError: module 'dashboard_app.views' has no attribute 'password_reset_request'
Exception in thread django-main-thread:
Traceback (most recent call last):
  File "/usr/lib/python3.8/threading.py", line 932, in _bootstrap_inner
    self.run()
  File "/usr/lib/python3.8/threading.py", line 870, in run
    self._target(*self._args, **self._kwargs)
  File "/var/www/uwsgi/dashboard/venv/lib/python3.8/site-packages/django/utils/autoreload.py", line 64, in wrapper
    fn(*args, **kwargs)
  File "/var/www/uwsgi/dashboard/venv/lib/python3.8/site-packages/django/core/management/commands/runserver.py", line 133, in inner_run
    self.check(display_num_errors=True)
  File "/var/www/uwsgi/dashboard/venv/lib/python3.8/site-packages/django/core/management/base.py", line 485, in check
    all_issues = checks.run_checks(
  File "/var/www/uwsgi/dashboard/venv/lib/python3.8/site-packages/django/core/checks/registry.py", line 88, in run_checks
    new_errors = check(app_configs=app_configs, databases=databases)
  File "/var/www/uwsgi/dashboard/venv/lib/python3.8/site-packages/django/core/checks/urls.py", line 14, in check_url_config
    return check_resolver(resolver)
  File "/var/www/uwsgi/dashboard/venv/lib/python3.8/site-packages/django/core/checks/urls.py", line 24, in check_resolver
    return check_method()
  File "/var/www/uwsgi/dashboard/venv/lib/python3.8/site-packages/django/urls/resolvers.py", line 494, in check
    for pattern in self.url_patterns:
  File "/var/www/uwsgi/dashboard/venv/lib/python3.8/site-packages/django/utils/functional.py", line 57, in __get__
    res = instance.__dict__[self.name] = self.func(instance)
  File "/var/www/uwsgi/dashboard/venv/lib/python3.8/site-packages/django/urls/resolvers.py", line 715, in url_patterns
    patterns = getattr(self.urlconf_module, "urlpatterns", self.urlconf_module)
  File "/var/www/uwsgi/dashboard/venv/lib/python3.8/site-packages/django/utils/functional.py", line 57, in __get__
    res = instance.__dict__[self.name] = self.func(instance)
  File "/var/www/uwsgi/dashboard/venv/lib/python3.8/site-packages/django/urls/resolvers.py", line 708, in urlconf_module
    return import_module(self.urlconf_name)
  File "/usr/lib/python3.8/importlib/__init__.py", line 127, in import_module
    return _bootstrap._gcd_import(name[level:], package, level)
  File "<frozen importlib._bootstrap>", line 1014, in _gcd_import
  File "<frozen importlib._bootstrap>", line 991, in _find_and_load
  File "<frozen importlib._bootstrap>", line 975, in _find_and_load_unlocked
  File "<frozen importlib._bootstrap>", line 671, in _load_unlocked
  File "<frozen importlib._bootstrap_external>", line 848, in exec_module
  File "<frozen importlib._bootstrap>", line 219, in _call_with_frames_removed
  File "/var/www/uwsgi/dashboard/dashboard/urls.py", line 23, in <module>
    path('api/', include('dashboard_app.api_urls')),
  File "/var/www/uwsgi/dashboard/venv/lib/python3.8/site-packages/django/urls/conf.py", line 38, in include
    urlconf_module = import_module(urlconf_module)
  File "/usr/lib/python3.8/importlib/__init__.py", line 127, in import_module
    return _bootstrap._gcd_import(name[level:], package, level)
  File "<frozen importlib._bootstrap>", line 1014, in _gcd_import
  File "<frozen importlib._bootstrap>", line 991, in _find_and_load
  File "<frozen importlib._bootstrap>", line 975, in _find_and_load_unlocked
  File "<frozen importlib._bootstrap>", line 671, in _load_unlocked
  File "<frozen importlib._bootstrap_external>", line 848, in exec_module
  File "<frozen importlib._bootstrap>", line 219, in _call_with_frames_removed
  File "/var/www/uwsgi/dashboard/dashboard_app/api_urls.py", line 19, in <module>
    path('password-reset/', views.password_reset_request, name='password_reset_request'),
AttributeError: module 'dashboard_app.views' has no attribute 'password_reset_request'
Performing system checks...

Performing system checks...

Performing system checks...

Performing system checks...

System check identified no issues (0 silenced).
March 30, 2025 - 06:25:00
Django version 4.2.16, using settings 'dashboard.settings'
Starting development server at http://0.0.0.0:8000/
Quit the server with CONTROL-C.

Performing system checks...

System check identified no issues (0 silenced).
March 30, 2025 - 06:25:00
Django version 4.2.16, using settings 'dashboard.settings'
Starting development server at http://0.0.0.0:8000/
Quit the server with CONTROL-C.

Performing system checks...

System check identified no issues (0 silenced).
March 30, 2025 - 06:25:00
Django version 4.2.16, using settings 'dashboard.settings'
Starting development server at http://0.0.0.0:8000/
Quit the server with CONTROL-C.

Performing system checks...

System check identified no issues (0 silenced).
March 30, 2025 - 06:34:21
Django version 4.2.16, using settings 'dashboard.settings'
Starting development server at http://0.0.0.0:8000/
Quit the server with CONTROL-C.

Performing system checks...

System check identified no issues (0 silenced).
March 30, 2025 - 06:34:21
Django version 4.2.16, using settings 'dashboard.settings'
Starting development server at http://0.0.0.0:8000/
Quit the server with CONTROL-C.

Performing system checks...

System check identified no issues (0 silenced).
March 30, 2025 - 06:34:21
Django version 4.2.16, using settings 'dashboard.settings'
Starting development server at http://0.0.0.0:8000/
Quit the server with CONTROL-C.

Performing system checks...

System check identified no issues (0 silenced).
March 30, 2025 - 06:34:45
Django version 4.2.16, using settings 'dashboard.settings'
Starting development server at http://0.0.0.0:8000/
Quit the server with CONTROL-C.

Performing system checks...

System check identified no issues (0 silenced).
March 30, 2025 - 06:34:44
Django version 4.2.16, using settings 'dashboard.settings'
Starting development server at http://0.0.0.0:8000/
Quit the server with CONTROL-C.

Performing system checks...

System check identified no issues (0 silenced).
March 30, 2025 - 06:34:44
Django version 4.2.16, using settings 'dashboard.settings'
Starting development server at http://0.0.0.0:8000/
Quit the server with CONTROL-C.

Performing system checks...

System check identified no issues (0 silenced).
March 30, 2025 - 06:34:48
Django version 4.2.16, using settings 'dashboard.settings'
Starting development server at http://0.0.0.0:8000/
Quit the server with CONTROL-C.

Performing system checks...

System check identified no issues (0 silenced).
March 30, 2025 - 06:34:48
Django version 4.2.16, using settings 'dashboard.settings'
Starting development server at http://0.0.0.0:8000/
Quit the server with CONTROL-C.

Performing system checks...

System check identified no issues (0 silenced).
March 30, 2025 - 06:34:47
Django version 4.2.16, using settings 'dashboard.settings'
Starting development server at http://0.0.0.0:8000/
Quit the server with CONTROL-C.

Performing system checks...

System check identified no issues (0 silenced).
March 30, 2025 - 06:34:59
Django version 4.2.16, using settings 'dashboard.settings'
Starting development server at http://0.0.0.0:8000/
Quit the server with CONTROL-C.

Performing system checks...

System check identified no issues (0 silenced).
March 30, 2025 - 06:34:59
Django version 4.2.16, using settings 'dashboard.settings'
Starting development server at http://0.0.0.0:8000/
Quit the server with CONTROL-C.

Performing system checks...

System check identified no issues (0 silenced).
March 30, 2025 - 06:34:59
Django version 4.2.16, using settings 'dashboard.settings'
Starting development server at http://0.0.0.0:8000/
Quit the server with CONTROL-C.

System check identified some issues:

WARNINGS:
?: settings.ACCOUNT_AUTHENTICATION_METHOD is deprecated, use: settings.ACCOUNT_LOGIN_METHODS = {'email'}
?: settings.ACCOUNT_LOGIN_ATTEMPTS_LIMIT/TIMEOUT is deprecated, use: settings.ACCOUNT_RATE_LIMITS['login_failed']

System check identified 2 issues (0 silenced).
System check identified some issues:

WARNINGS:
?: settings.ACCOUNT_AUTHENTICATION_METHOD is deprecated, use: settings.ACCOUNT_LOGIN_METHODS = {'email'}
?: settings.ACCOUNT_LOGIN_ATTEMPTS_LIMIT/TIMEOUT is deprecated, use: settings.ACCOUNT_RATE_LIMITS['login_failed']

System check identified 2 issues (0 silenced).
System check identified some issues:

WARNINGS:
?: settings.ACCOUNT_AUTHENTICATION_METHOD is deprecated, use: settings.ACCOUNT_LOGIN_METHODS = {'email'}
?: settings.ACCOUNT_LOGIN_ATTEMPTS_LIMIT/TIMEOUT is deprecated, use: settings.ACCOUNT_RATE_LIMITS['login_failed']

System check identified 2 issues (0 silenced).
Performing system checks...

March 30, 2025 - 06:36:06
Django version 4.2.16, using settings 'dashboard.settings'
Starting development server at http://0.0.0.0:8000/
Quit the server with CONTROL-C.

Performing system checks...

March 30, 2025 - 06:36:06
Django version 4.2.16, using settings 'dashboard.settings'
Starting development server at http://0.0.0.0:8000/
Quit the server with CONTROL-C.

Performing system checks...

March 30, 2025 - 06:36:06
Django version 4.2.16, using settings 'dashboard.settings'
Starting development server at http://0.0.0.0:8000/
Quit the server with CONTROL-C.

System check identified some issues:

WARNINGS:
?: settings.ACCOUNT_AUTHENTICATION_METHOD is deprecated, use: settings.ACCOUNT_LOGIN_METHODS = {'email'}
?: settings.ACCOUNT_LOGIN_ATTEMPTS_LIMIT/TIMEOUT is deprecated, use: settings.ACCOUNT_RATE_LIMITS['login_failed']

System check identified 2 issues (0 silenced).
System check identified some issues:

WARNINGS:
?: settings.ACCOUNT_AUTHENTICATION_METHOD is deprecated, use: settings.ACCOUNT_LOGIN_METHODS = {'email'}
?: settings.ACCOUNT_LOGIN_ATTEMPTS_LIMIT/TIMEOUT is deprecated, use: settings.ACCOUNT_RATE_LIMITS['login_failed']

System check identified 2 issues (0 silenced).
System check identified some issues:

WARNINGS:
?: settings.ACCOUNT_AUTHENTICATION_METHOD is deprecated, use: settings.ACCOUNT_LOGIN_METHODS = {'email'}
?: settings.ACCOUNT_LOGIN_ATTEMPTS_LIMIT/TIMEOUT is deprecated, use: settings.ACCOUNT_RATE_LIMITS['login_failed']

System check identified 2 issues (0 silenced).
Performing system checks...

March 30, 2025 - 06:36:35
Django version 4.2.16, using settings 'dashboard.settings'
Starting development server at http://0.0.0.0:8000/
Quit the server with CONTROL-C.

Performing system checks...

March 30, 2025 - 06:36:35
Django version 4.2.16, using settings 'dashboard.settings'
Starting development server at http://0.0.0.0:8000/
Quit the server with CONTROL-C.

Performing system checks...

March 30, 2025 - 06:36:36
Django version 4.2.16, using settings 'dashboard.settings'
Starting development server at http://0.0.0.0:8000/
Quit the server with CONTROL-C.

System check identified some issues:

WARNINGS:
?: settings.ACCOUNT_AUTHENTICATION_METHOD is deprecated, use: settings.ACCOUNT_LOGIN_METHODS = {'email'}
?: settings.ACCOUNT_LOGIN_ATTEMPTS_LIMIT/TIMEOUT is deprecated, use: settings.ACCOUNT_RATE_LIMITS['login_failed']

System check identified 2 issues (0 silenced).
System check identified some issues:

WARNINGS:
?: settings.ACCOUNT_AUTHENTICATION_METHOD is deprecated, use: settings.ACCOUNT_LOGIN_METHODS = {'email'}
?: settings.ACCOUNT_LOGIN_ATTEMPTS_LIMIT/TIMEOUT is deprecated, use: settings.ACCOUNT_RATE_LIMITS['login_failed']

System check identified 2 issues (0 silenced).
System check identified some issues:

WARNINGS:
?: settings.ACCOUNT_AUTHENTICATION_METHOD is deprecated, use: settings.ACCOUNT_LOGIN_METHODS = {'email'}
?: settings.ACCOUNT_LOGIN_ATTEMPTS_LIMIT/TIMEOUT is deprecated, use: settings.ACCOUNT_RATE_LIMITS['login_failed']

System check identified 2 issues (0 silenced).
Performing system checks...

March 30, 2025 - 06:36:58
Django version 4.2.16, using settings 'dashboard.settings'
Starting development server at http://0.0.0.0:8000/
Quit the server with CONTROL-C.

Performing system checks...

March 30, 2025 - 06:36:58
Django version 4.2.16, using settings 'dashboard.settings'
Starting development server at http://0.0.0.0:8000/
Quit the server with CONTROL-C.

Performing system checks...

March 30, 2025 - 06:36:58
Django version 4.2.16, using settings 'dashboard.settings'
Starting development server at http://0.0.0.0:8000/
Quit the server with CONTROL-C.

System check identified some issues:

WARNINGS:
?: settings.ACCOUNT_AUTHENTICATION_METHOD is deprecated, use: settings.ACCOUNT_LOGIN_METHODS = {'email'}
?: settings.ACCOUNT_LOGIN_ATTEMPTS_LIMIT/TIMEOUT is deprecated, use: settings.ACCOUNT_RATE_LIMITS['login_failed']

System check identified 2 issues (0 silenced).
System check identified some issues:

WARNINGS:
?: settings.ACCOUNT_AUTHENTICATION_METHOD is deprecated, use: settings.ACCOUNT_LOGIN_METHODS = {'email'}
?: settings.ACCOUNT_LOGIN_ATTEMPTS_LIMIT/TIMEOUT is deprecated, use: settings.ACCOUNT_RATE_LIMITS['login_failed']

System check identified 2 issues (0 silenced).
System check identified some issues:

WARNINGS:
?: settings.ACCOUNT_AUTHENTICATION_METHOD is deprecated, use: settings.ACCOUNT_LOGIN_METHODS = {'email'}
?: settings.ACCOUNT_LOGIN_ATTEMPTS_LIMIT/TIMEOUT is deprecated, use: settings.ACCOUNT_RATE_LIMITS['login_failed']

System check identified 2 issues (0 silenced).
Performing system checks...

March 30, 2025 - 06:37:29
Django version 4.2.16, using settings 'dashboard.settings'
Starting development server at http://0.0.0.0:8000/
Quit the server with CONTROL-C.

Performing system checks...

March 30, 2025 - 06:37:29
Django version 4.2.16, using settings 'dashboard.settings'
Starting development server at http://0.0.0.0:8000/
Quit the server with CONTROL-C.

Performing system checks...

March 30, 2025 - 06:37:29
Django version 4.2.16, using settings 'dashboard.settings'
Starting development server at http://0.0.0.0:8000/
Quit the server with CONTROL-C.

System check identified some issues:

WARNINGS:
?: settings.ACCOUNT_AUTHENTICATION_METHOD is deprecated, use: settings.ACCOUNT_LOGIN_METHODS = {'email'}
?: settings.ACCOUNT_LOGIN_ATTEMPTS_LIMIT/TIMEOUT is deprecated, use: settings.ACCOUNT_RATE_LIMITS['login_failed']

System check identified 2 issues (0 silenced).
System check identified some issues:

WARNINGS:
?: settings.ACCOUNT_AUTHENTICATION_METHOD is deprecated, use: settings.ACCOUNT_LOGIN_METHODS = {'email'}
?: settings.ACCOUNT_LOGIN_ATTEMPTS_LIMIT/TIMEOUT is deprecated, use: settings.ACCOUNT_RATE_LIMITS['login_failed']

System check identified 2 issues (0 silenced).
System check identified some issues:

WARNINGS:
?: settings.ACCOUNT_AUTHENTICATION_METHOD is deprecated, use: settings.ACCOUNT_LOGIN_METHODS = {'email'}
?: settings.ACCOUNT_LOGIN_ATTEMPTS_LIMIT/TIMEOUT is deprecated, use: settings.ACCOUNT_RATE_LIMITS['login_failed']

System check identified 2 issues (0 silenced).
Performing system checks...

March 30, 2025 - 06:37:48
Django version 4.2.16, using settings 'dashboard.settings'
Starting development server at http://0.0.0.0:8000/
Quit the server with CONTROL-C.

Performing system checks...

March 30, 2025 - 06:37:48
Django version 4.2.16, using settings 'dashboard.settings'
Starting development server at http://0.0.0.0:8000/
Quit the server with CONTROL-C.

Performing system checks...

March 30, 2025 - 06:37:48
Django version 4.2.16, using settings 'dashboard.settings'
Starting development server at http://0.0.0.0:8000/
Quit the server with CONTROL-C.

System check identified some issues:

WARNINGS:
?: settings.ACCOUNT_AUTHENTICATION_METHOD is deprecated, use: settings.ACCOUNT_LOGIN_METHODS = {'email'}
?: settings.ACCOUNT_LOGIN_ATTEMPTS_LIMIT/TIMEOUT is deprecated, use: settings.ACCOUNT_RATE_LIMITS['login_failed']

System check identified 2 issues (0 silenced).
System check identified some issues:

WARNINGS:
?: settings.ACCOUNT_AUTHENTICATION_METHOD is deprecated, use: settings.ACCOUNT_LOGIN_METHODS = {'email'}
?: settings.ACCOUNT_LOGIN_ATTEMPTS_LIMIT/TIMEOUT is deprecated, use: settings.ACCOUNT_RATE_LIMITS['login_failed']

System check identified 2 issues (0 silenced).
System check identified some issues:

WARNINGS:
?: settings.ACCOUNT_AUTHENTICATION_METHOD is deprecated, use: settings.ACCOUNT_LOGIN_METHODS = {'email'}
?: settings.ACCOUNT_LOGIN_ATTEMPTS_LIMIT/TIMEOUT is deprecated, use: settings.ACCOUNT_RATE_LIMITS['login_failed']

System check identified 2 issues (0 silenced).
Performing system checks...

March 30, 2025 - 06:38:11
Django version 4.2.16, using settings 'dashboard.settings'
Starting development server at http://0.0.0.0:8000/
Quit the server with CONTROL-C.

Performing system checks...

March 30, 2025 - 06:38:11
Django version 4.2.16, using settings 'dashboard.settings'
Starting development server at http://0.0.0.0:8000/
Quit the server with CONTROL-C.

System check identified some issues:

WARNINGS:
?: settings.ACCOUNT_AUTHENTICATION_METHOD is deprecated, use: settings.ACCOUNT_LOGIN_METHODS = {'email'}
?: settings.ACCOUNT_LOGIN_ATTEMPTS_LIMIT/TIMEOUT is deprecated, use: settings.ACCOUNT_RATE_LIMITS['login_failed']

System check identified 2 issues (0 silenced).
System check identified some issues:

WARNINGS:
?: settings.ACCOUNT_AUTHENTICATION_METHOD is deprecated, use: settings.ACCOUNT_LOGIN_METHODS = {'email'}
?: settings.ACCOUNT_LOGIN_ATTEMPTS_LIMIT/TIMEOUT is deprecated, use: settings.ACCOUNT_RATE_LIMITS['login_failed']

System check identified 2 issues (0 silenced).
Performing system checks...

March 30, 2025 - 06:38:11
Django version 4.2.16, using settings 'dashboard.settings'
Starting development server at http://0.0.0.0:8000/
Quit the server with CONTROL-C.

System check identified some issues:

WARNINGS:
?: settings.ACCOUNT_AUTHENTICATION_METHOD is deprecated, use: settings.ACCOUNT_LOGIN_METHODS = {'email'}
?: settings.ACCOUNT_LOGIN_ATTEMPTS_LIMIT/TIMEOUT is deprecated, use: settings.ACCOUNT_RATE_LIMITS['login_failed']

System check identified 2 issues (0 silenced).
Performing system checks...

March 30, 2025 - 06:38:33
Django version 4.2.16, using settings 'dashboard.settings'
Starting development server at http://0.0.0.0:8000/
Quit the server with CONTROL-C.

Performing system checks...

March 30, 2025 - 06:38:33
Django version 4.2.16, using settings 'dashboard.settings'
Starting development server at http://0.0.0.0:8000/
Quit the server with CONTROL-C.

Performing system checks...

March 30, 2025 - 06:38:33
Django version 4.2.16, using settings 'dashboard.settings'
Starting development server at http://0.0.0.0:8000/
Quit the server with CONTROL-C.

System check identified some issues:

WARNINGS:
?: settings.ACCOUNT_AUTHENTICATION_METHOD is deprecated, use: settings.ACCOUNT_LOGIN_METHODS = {'email'}
?: settings.ACCOUNT_LOGIN_ATTEMPTS_LIMIT/TIMEOUT is deprecated, use: settings.ACCOUNT_RATE_LIMITS['login_failed']

System check identified 2 issues (0 silenced).
System check identified some issues:

WARNINGS:
?: settings.ACCOUNT_AUTHENTICATION_METHOD is deprecated, use: settings.ACCOUNT_LOGIN_METHODS = {'email'}
?: settings.ACCOUNT_LOGIN_ATTEMPTS_LIMIT/TIMEOUT is deprecated, use: settings.ACCOUNT_RATE_LIMITS['login_failed']

System check identified 2 issues (0 silenced).
System check identified some issues:

WARNINGS:
?: settings.ACCOUNT_AUTHENTICATION_METHOD is deprecated, use: settings.ACCOUNT_LOGIN_METHODS = {'email'}
?: settings.ACCOUNT_LOGIN_ATTEMPTS_LIMIT/TIMEOUT is deprecated, use: settings.ACCOUNT_RATE_LIMITS['login_failed']

System check identified 2 issues (0 silenced).
Performing system checks...

March 30, 2025 - 06:38:47
Django version 4.2.16, using settings 'dashboard.settings'
Starting development server at http://0.0.0.0:8000/
Quit the server with CONTROL-C.

Performing system checks...

March 30, 2025 - 06:38:47
Django version 4.2.16, using settings 'dashboard.settings'
Starting development server at http://0.0.0.0:8000/
Quit the server with CONTROL-C.

Performing system checks...

March 30, 2025 - 06:38:47
Django version 4.2.16, using settings 'dashboard.settings'
Starting development server at http://0.0.0.0:8000/
Quit the server with CONTROL-C.

System check identified some issues:

WARNINGS:
?: settings.ACCOUNT_AUTHENTICATION_METHOD is deprecated, use: settings.ACCOUNT_LOGIN_METHODS = {'email'}
?: settings.ACCOUNT_LOGIN_ATTEMPTS_LIMIT/TIMEOUT is deprecated, use: settings.ACCOUNT_RATE_LIMITS['login_failed']

System check identified 2 issues (0 silenced).
System check identified some issues:

WARNINGS:
?: settings.ACCOUNT_AUTHENTICATION_METHOD is deprecated, use: settings.ACCOUNT_LOGIN_METHODS = {'email'}
?: settings.ACCOUNT_LOGIN_ATTEMPTS_LIMIT/TIMEOUT is deprecated, use: settings.ACCOUNT_RATE_LIMITS['login_failed']

System check identified 2 issues (0 silenced).
System check identified some issues:

WARNINGS:
?: settings.ACCOUNT_AUTHENTICATION_METHOD is deprecated, use: settings.ACCOUNT_LOGIN_METHODS = {'email'}
?: settings.ACCOUNT_LOGIN_ATTEMPTS_LIMIT/TIMEOUT is deprecated, use: settings.ACCOUNT_RATE_LIMITS['login_failed']

System check identified 2 issues (0 silenced).
